Workbook

Sheet SB
B1: Service Building- Cooling Load Summary
B2: AREA DETAILS | H2: OCCUPANCY | K2: Ashrae Occupancy | O2: INSIDE CONDITIONS | Q2: FRESH AIR | V2: Exhaust Air | Z2: EQUIPMENT LOAD | AD2: LIGHTING | AG2: A.C CAPACITY
A3: Category | B3: # | C3: SPACE NUMBER | D3: SPACE | F3: AREA | G3: TOTAL Area | H3: By Space as per arch Plans | I3: As per Ashrae | J3: TOTAL | K3: Category | L3: Space Usage | M3: Density | N3: TOTAL | O3: TEMP | P3: RH % | Q3: l/s person | R3: l/s / sqm | S3: ACH | T3: L/S | U3: rounded L/S | V3: L/S/Unit | W3: # of Unit | X3: L/S | Y3: Rounded L/S | Z3: W / sqm | AA3: W | AB3: KW | AC3: Total KW | AD3: W/sqm | AE3: KW | AF3: KW | AG3: Total KW | AH3: Sensible KW | AI3: L/S | AJ3: E.D.B | AK3: E.W.B | AL3: L.D.B | AM3: L.W.B | AN3: L/S / sqm | AO3: W / sqm | AP3: COOLING UNIT
A4: Prep and Shrouding area | B4: 1 | C4: SB-001 | D4: Washing and Shrouding Room for Decomposed Corpses | E4: غرفة غسيل وتكفين الوفيات المتحللة | F4: 20 | G4: =F4 -> 20 | H4: 2 | J4: =H4 -> 2 | K4: Public Assembly Space | L4: Lobbies | M4: #N/A | N4: 0 | O4: 22 | P4: 50 | Q4: =VLOOKUP(A4,Data!A:D,4,FALSE) -> 0 | R4: =VLOOKUP(A4,Data!A:C,3,FALSE) -> 0 | S4: 2 | T4: =S4*F4*3/3.6 -> 33.333333 | U4: =CEILING(T4,5) -> 35 | X4: =T4/0.85 -> 39.215686 | Y4: =CEILING(X4,5) -> 40 | Z4: 0 | AA4: 0 | AB4: =(Z4*F4+AA4)/1000 -> 0 | AC4: =AB4 -> 0 | AD4: =VLOOKUP(A4,Data!A:F,6,FALSE) -> 10 | AE4: =AD4*F4/1000 -> 0.2 | AF4: =AE4 -> 0.2 | AI4: 2850 | AJ4: 23.3 | AK4: 16.5 | AL4: 13 | AM4: 12.4 | AN4: =AI4/G4 -> 142.5 | AO4: =AG4/G4*1000 -> 0 | AP4: RTU-01b
A5: Prep and Shrouding area | B5: 2 | C5: SB-002 | D5: Washing and Shrouding Room for Decomposed Corpses | E5: غرفة غسيل وتكفين الوفيات المتحللة | F5: 20 | G5: =F5 -> 20 | H5: 2 | J5: =H5 -> 2 | K5: 0 | L5: 0 | M5: #N/A | N5: =K5 -> 0 | O5: 22 | P5: 51 | Q5: =VLOOKUP(A5,Data!A:D,4,FALSE) -> 0 | R5: =VLOOKUP(A5,Data!A:C,3,FALSE) -> 0 | S5: 2 | T5: =S5*F5*3/3.6 -> 33.333333 | U5: =CEILING(T5,5) -> 35 | X5: =T5/0.85 -> 39.215686 | Y5: =CEILING(X5,5) -> 40 | Z5: 0 | AA5: 2700 | AB5: =(Z5*F5+AA5)/1000 -> 2.7 | AC5: =AB5 -> 2.7 | AD5: =VLOOKUP(A5,Data!A:F,6,FALSE) -> 10 | AE5: =AD5*F5/1000 -> 0.2 | AF5: =AE5 -> 0.2 | AI5: 3900 | AJ5: 23.4 | AK5: 16.7 | AL5: 13 | AM5: 12.4 | AN5: =AI5/G5 -> 195 | AO5: =AG5/G5*1000 -> 0 | AP5: RTU-01c
A6: Prep and Shrouding area | B6: 3 | C6: SB-003 | D6: Mortuary Refrigirator | E6: ثلاجة الموتي | F6: =5*8.7 -> 43.5 | G6: =F6 -> 43.5 | J6: =H6 -> 0 | K6: 0 | L6: 0 | M6: #N/A | N6: =K6 -> 0 | O6: 26 | P6: <60 | Q6: =VLOOKUP(A6,Data!A:D,4,FALSE) -> 0 | R6: =VLOOKUP(A6,Data!A:C,3,FALSE) -> 0 | S6: 2 | T6: =S6*F6*3/3.6 -> 72.5 | U6: =CEILING(T6,5) -> 75 | X6: =T6/0.85 -> 85.294118 | Y6: =CEILING(X6,5) -> 90 | Z6: 50 | AA6: 0 | AB6: =(Z6*F6+AA6)/1000 -> 2.175 | AC6: =AB6 -> 2.175 | AD6: =VLOOKUP(A6,Data!A:F,6,FALSE) -> 10 | AE6: =AD6*F6/1000 -> 0.435 | AF6: =AE6 -> 0.435 | AI6: 103 | AJ6: 24.8 | AK6: 8 | AL6: 12.5 | AM6: 1.7 | AN6: =AI6/G6 -> 2.3678161 | AO6: =AG6/G6*1000 -> 0 | AP6: MSIU-01
A7: mechanical/maintenance room | B7: 4 | C7: SB-004 | D7: Equipment Maintenance Workshop | E7: ورشة صيانة المعدات | F7: =5*8.8 -> 44 | G7: =F7 -> 44 | H7: 2 | J7: =H7 -> 2 | K7: 0 | L7: 0 | M7: #N/A | N7: =K7 -> 0 | O7: 22 | P7: <60 | Q7: =VLOOKUP(A7,Data!A:D,4,FALSE) -> 0 | R7: =VLOOKUP(A7,Data!A:C,3,FALSE) -> 0.3 | T7: =Q7*H7+R7*F7 -> 13.2 | U7: =CEILING(T7,5) -> 15 | X7: =T7*0.85 -> 11.22 | Y7: 10 | Z7: 0 | AA7: 250 | AB7: =(Z7*F7+AA7)/1000 -> 0.25 | AC7: =AB7 -> 0.25 | AD7: =VLOOKUP(A7,Data!A:F,6,FALSE) -> 10 | AE7: =AD7*F7/1000 -> 0.44 | AF7: =AE7 -> 0.44 | AI7: 70 | AJ7: 22.8 | AK7: 16.9 | AL7: 13.6 | AM7: 13.1 | AN7: =AI7/G7 -> 1.5909091 | AO7: =AG7/G7*1000 -> 0 | AP7: VRF-01
A8: Laundry Room | B8: 5 | C8: SB-005 | D8: Sheet Washing Room | E8: غرفة غسيل الشراشف | F8: =4*6 -> 24 | G8: =F8 -> 24 | J8: =H8 -> 0 | K8: 0 | L8: 0 | M8: #N/A | N8: =K8 -> 0 | O8: 22 | P8: <60 | Q8: =VLOOKUP(A8,Data!A:D,4,FALSE) -> 0 | R8: =VLOOKUP(A8,Data!A:C,3,FALSE) -> 0 | T8: =Q8*H8+R8*F8 -> 0 | U8: =CEILING(T8,5) -> 0 | X8: =T8/0.85 -> 0 | Y8: =CEILING(X8,5) -> 0 | Z8: 0 | AA8: 250 | AB8: =(Z8*F8+AA8)/1000 -> 0.25 | AC8: =AB8 -> 0.25 | AD8: =VLOOKUP(A8,Data!A:F,6,FALSE) -> 10 | AE8: =AD8*F8/1000 -> 0.24 | AF8: =AE8 -> 0.24 | AI8: 70 | AJ8: 22.8 | AK8: 16.9 | AL8: 13.6 | AM8: 13.1 | AN8: =AI8/G8 -> 2.9166667 | AO8: =AG8/G8*1000 -> 0 | AP8: VRF-01
A9: bathroom | B9: 7 | C9: SB-006 | D9: Excavator Workers Toilet | E9: دورة مياه عمال الحفر | F9: =5*7.7 -> 38.5 | G9: =F9 -> 38.5 | H9: 6 | J9: =H9 -> 6 | K9: 0 | L9: 0 | M9: #N/A | N9: =K9 -> 0 | O9: 26 | P9: <60 | Q9: =VLOOKUP(A9,Data!A:D,4,FALSE) -> 0 | R9: =VLOOKUP(A9,Data!A:C,3,FALSE) -> 0 | T9: =X9*0.85 -> 127.5 | U9: =CEILING(T9,5) -> 130 | V9: 25 | W9: 6 | X9: =W9*V9 -> 150 | Y9: =CEILING(X9,1) -> 150 | Z9: 50 | AA9: 0 | AB9: =(Z9*F9+AA9)/1000 -> 1.925 | AC9: =AB9 -> 1.925 | AD9: =VLOOKUP(A9,Data!A:F,6,FALSE) -> 10 | AE9: =AD9*F9/1000 -> 0.385 | AF9: =AE9 -> 0.385 | AI9: 19 | AJ9: 24 | AK9: 7.7 | AL9: 11 | AM9: 0.8 | AN9: =AI9/G9 -> 0.49350649 | AO9: =AG9/G9*1000 -> 0 | AP9: MSIU-01
A10: Waiting Area | B10: 8 | C10: SB-007 | D10: Excavator Workers Resting Area | E10: استراحة عمال الحفر | F10: 38.5 | G10: =F10 -> 38.5 | H10: 17 | J10: =H10 -> 17 | K10: 0 | L10: 0 | M10: #N/A | N10: =K10 -> 0 | O10: 22 | P10: <60 | Q10: =VLOOKUP(A10,Data!A:D,4,FALSE) -> 3.8 | R10: =VLOOKUP(A10,Data!A:C,3,FALSE) -> 0.3 | T10: =Q10*H10+R10*F10 -> 76.15 | U10: =CEILING(T10,5) -> 80 | X10: =T10*0.85 -> 64.7275 | Y10: =CEILING(X10,5) -> 65 | Z10: 0 | AA10: 250 | AB10: =(Z10*F10+AA10)/1000 -> 0.25 | AC10: =AB10 -> 0.25 | AD10: =VLOOKUP(A10,Data!A:F,6,FALSE) -> 10 | AE10: =AD10*F10/1000 -> 0.385 | AF10: =AE10 -> 0.385 | AI10: 71 | AJ10: 22.7 | AK10: 16.8 | AL10: 13.3 | AM10: 12.8 | AN10: =AI10/G10 -> 1.8441558 | AO10: =AG10/G10*1000 -> 0 | AP10: VRF-01
A11: Storage | B11: 9 | C11: SB-008 | D11: Main Warehouse for Processing Materials | E11: مستودع رئيسي لمواد التجهيز | F11: 38.5 | G11: =F11 -> 38.5 | J11: =H11 -> 0 | K11: 0 | L11: 0 | M11: #N/A | N11: =K11 -> 0 | O11: 22 | P11: <60 | Q11: =VLOOKUP(A11,Data!A:D,4,FALSE) -> 0 | R11: =VLOOKUP(A11,Data!A:C,3,FALSE) -> 0 | T11: =Q11*H11+R11*F11 -> 0 | U11: =CEILING(T11,5) -> 0 | X11: =T11*0.85 -> 0 | Y11: =CEILING(X11,5) -> 0 | Z11: 0 | AA11: 2000 | AB11: =(Z11*F11+AA11)/1000 -> 2 | AC11: =AB11 -> 2 | AD11: =VLOOKUP(A11,Data!A:F,6,FALSE) -> 10 | AE11: =AD11*F11/1000 -> 0.385 | AF11: =AE11 -> 0.385 | AI11: 216 | AJ11: 22.5 | AK11: 10 | AL11: 13 | AM11: 5.6 | AN11: =AI11/G11 -> 5.6103896 | AO11: =AG11/G11*1000 -> 0 | AP11: VRF-02
A12: Storage | B12: 10 | C12: SB-009 | D12: Al-Baqi' Equipement Warehouse | E12: مخزن معدات البقيع | F12: =6*8 -> 48 | G12: =F12 -> 48 | J12: 0 | K12: 0 | L12: 0 | M12: #N/A | N12: =K12 -> 0 | O12: 22 | P12: <60 | Q12: =VLOOKUP(A12,Data!A:D,4,FALSE) -> 0 | R12: =VLOOKUP(A12,Data!A:C,3,FALSE) -> 0 | T12: =Q12*H12+R12*F12 -> 0 | U12: =CEILING(T12,5) -> 0 | X12: =T12*0.85 -> 0 | Y12: =CEILING(X12,5) -> 0 | Z12: 0 | AA12: 0 | AB12: =(Z12*F12+AA12)/1000 -> 0 | AC12: =AB12 -> 0 | AD12: =VLOOKUP(A12,Data!A:F,6,FALSE) -> 10 | AE12: =AD12*F12/1000 -> 0.48 | AF12: =AE12 -> 0.48 | AI12: 103 | AJ12: 22.7 | AK12: 16.9 | AL12: 13.1 | AM12: 12.5 | AN12: =AI12/G12 -> 2.1458333 | AO12: =AG12/G12*1000 -> 0 | AP12: VRF-02
A13: Storage | B13: 11 | C13: SB-010 | D13: Water Bottle Cooling Room | E13: غرفة تبريد عبوات مياه الشرب | F13: 51 | G13: =F13 -> 51 | J13: =H13 -> 0 | K13: 0 | L13: 0 | M13: #N/A | N13: =K13 -> 0 | O13: 22 | P13: <60 | Q13: =VLOOKUP(A13,Data!A:D,4,FALSE) -> 0 | R13: =VLOOKUP(A13,Data!A:C,3,FALSE) -> 0 | T13: =Q13*H13+R13*F13 -> 0 | U13: =CEILING(T13,5) -> 0 | X13: =T13*0.85 -> 0 | Y13: =CEILING(X13,5) -> 0 | Z13: 0 | AA13: 500 | AB13: =(Z13*F13+AA13)/1000 -> 0.5 | AC13: =AB13 -> 0.5 | AD13: =VLOOKUP(A13,Data!A:F,6,FALSE) -> 10 | AE13: =AD13*F13/1000 -> 0.51 | AF13: =AE13 -> 0.51 | AI13: 69 | AJ13: 22.9 | AK13: 11.8 | AL13: 13.4 | AM13: 7.6 | AN13: =AI13/G13 -> 1.3529412 | AO13: =AG13/G13*1000 -> 0 | AP13: VRF-02
B14: Totals and Averages | G14: =#REF! -> #REF! | H14: =#REF! -> #REF! | K14: =#REF! -> #REF! | O14: - | Q14: =#REF! & " L/S" -> #REF! | Z14: =ROUND(SUM(AC4:AC13),0) & " KW" -> 10 KW | AD14: =ROUND(SUM(AF4:AF13),0) & " KW" -> 4 KW | AG14: =SUM(AG4:AG13) -> 0 | AH14: =SUM(AH4:AH13) -> 0 | AI14: =SUM(AI4:AI13) -> 7471 | AJ14: - | AK14: - | AL14: - | AM14: - | AN14: =AI14/G14 -> #REF! | AO14: =AG14/G14*1000 -> #REF! | AP14: -

Sheet MB
B1: Cemetary Main Building- Cooling Load Summary
B2: AREA DETAILS | I2: OCCUPANCY | L2: Ashrae Occupancy | P2: INSIDE CONDITIONS | R2: FRESH AIR | W2: Transfer | X2: EXHAUST AIR | AB2: Exhaust | AC2: Pressurization | AD2: Space Pressurization | AE2: ACH VALUE | AF2: ACH BETWEEN 03 AND 0..8 | AG2: EQUIPMENT LOAD | AK2: LIGHTING | AN2: A.C CAPACITY
B3: =SUBTOTAL(109,G5:H115) -> 2606.56 | R3: =SUBTOTAL(9,(V5:V115)) -> 1370 | X3: =SUBTOTAL(9,(AB5:AB115)) -> -815
A4: Category | B4: # | D4: SPACE NUMBER | E4: SPACE | G4: AREA | H4: TOTAL Area | I4: By Space as per arch Plans | J4: As per Ashrae | K4: TOTAL | L4: Category | M4: Space Usage | N4: Density | O4: TOTAL | P4: TEMP | Q4: RH % | R4: l/s person | S4: l/s / sqm | T4: ACH | U4: L/S | V4: Rounded L/S | X4: L/S/Unit or meter | Y4: # of Unit | Z4: L/S | AA4: Rounded L/S | AG4: W / sqm | AH4: W | AI4: KW | AJ4: Total KW | AK4: W/sqm | AL4: KW | AM4: KW | AN4: Total KW | AO4: Sensible KW | AP4: Quantity | AQ4: Sensible Cooling Load per FCU | AR4: Selected Sensible Load | AS4: Supply L/S | AT4: Return L/S | AU4: E.D.B | AV4: E.W.B | AW4: L.D.B | AX4: L.W.B | AY4: L/S / sqm | AZ4: Btu/hr/ sqm | BA4: COOLING UNIT | BB4: FCU SELECTION
A5: Storage | B5: 1 | C5: Group 6 | D5: GF-001 | E5: Sub-Store for Supplies | F5: خزن فرعي لمستلزمات التجهيز | G5: 16 | H5: =G5 -> 16 | I5: 1 | K5: =I5 -> 1 | L5: 0 | M5: 0 | N5: =VLOOKUP(A5,Data!A:B,2,FALSE) -> 2 | O5: =L5 -> 0 | P5: 22 | Q5: 50 | R5: =VLOOKUP(A5,Data!A:D,4,FALSE) -> 0 | S5: =VLOOKUP(A5,Data!A:C,3,FALSE) -> 0 | U5: =R5*I5+S5*G5 -> 0 | V5: 11 | Z5: =U5/0.85 -> 0 | AA5: 25 | AB5: -15 | AD5: =IF(V5+W5+AB5 > 0, "Positive", IF(V5-+W5+AB5 < 0, "Negative", "Neutral")) -> Negative | AE5: =ROUND(ABS((V5+AB5+W5+AC5)*3.6)/(G5*3),2) -> 0.3 | AF5: =AND(AE5>=0.3,AE5<=0.8) -> TRUE | AK5: =VLOOKUP(A5,Data!A:F,6,FALSE) -> 10 | AL5: =AK5*G5/1000 -> 0.16 | AM5: =AL5 -> 0.16 | AP5: 1 | AQ5: =AO5/AP5 -> 0 | AR5: 2.3 | AS5: =IF(AR5<=Sheet2!$D$2,Sheet2!$C$2,IF(AR5<=Sheet2!$D$3,Sheet2!$C$3,IF(AR5<=Sheet2!$D$4,Sheet2!$C$4,IF(AR5<=Sheet2!$D$5,Sheet2!$C$5,IF(AR5<=Sheet2!$D$6,Sheet2!$C$6,IF(AR5<=Sheet2!$D$7,Sheet2!$C$7,IF(AR5<=Sheet2!$D$8,Sheet2!$C$8,IF(AR5<=Sheet2!$D$9,Sheet2!$C$9,IF(AR5<=Sheet2!$D$10,Sheet2!$C$10,IF(AR5<=Sheet2!$D$11,Sheet2!$C$11,0)))))))))) -> 158 | AT5: =AS5-V5 -> 147 | AY5: =AS5/H5 -> 9.875 | AZ5: =(AR5/H5*1000)*3.4 -> 488.75 | BA5: VRV-GF-01 | BB5: =IF(AR5<=Sheet2!$D$2,Sheet2!$B$2,IF(AR5<=Sheet2!$D$3,Sheet2!$B$3,IF(AR5<=Sheet2!$D$4,Sheet2!$B$4,IF(AR5<=Sheet2!$D$5,Sheet2!$B$5,IF(AR5<=Sheet2!$D$6,Sheet2!$B$6,IF(AR5<=Sheet2!$D$7,Sheet2!$B$7,IF(AR5<=Sheet2!$D$8,Sheet2!$B$8,IF(AR5<=Sheet2!$D$9,Sheet2!$B$9,IF(AR5<=Sheet2!$D$10,Sheet2!$B$10,IF(AR5<=Sheet2!$D$11,Sheet2!$B$11,0)))))))))) -> FXSQ32A
A6: Trash | B6: 2 | C6: Group 6 | D6: GF-002 | E6: Garbage Room | F6: غرفة نفايات | G6: 12.5 | H6: =G6 -> 12.5 | I6: 1 | K6: =I6 -> 1 | L6: 0 | M6: 0 | N6: =VLOOKUP(A6,Data!A:B,2,FALSE) -> 0 | O6: =L6 -> 0 | P6: 22 | Q6: 51 | R6: =VLOOKUP(A6,Data!A:D,4,FALSE) -> 0 | S6: =VLOOKUP(A6,Data!A:C,3,FALSE) -> 0 | V6: 60 | Z6: =65 -> 65 | AA6: =CEILING(Z6,1) -> 65 | AB6: =(CEILING(AA6,1))*-1 -> -65 | AD6: =IF(V6+W6+AB6 > 0, "Positive", IF(V6-+W6+AB6 < 0, "Negative", "Neutral")) -> Negative | AE6: =ROUND(ABS((V6+AB6+W6+AC6)*3.6)/(G6*3),2) -> 0.48 | AF6: =AND(AE6>=0.3,AE6<=0.8) -> TRUE | AK6: =VLOOKUP(A6,Data!A:F,6,FALSE) -> 0 | AL6: =AK6*G6/1000 -> 0 | AM6: =AL6 -> 0 | AP6: 1 | AQ6: =AO6/AP6 -> 0 | AR6: 1 | AS6: =IF(AR6<=Sheet2!$D$2,Sheet2!$C$2,IF(AR6<=Sheet2!$D$3,Sheet2!$C$3,IF(AR6<=Sheet2!$D$4,Sheet2!$C$4,IF(AR6<=Sheet2!$D$5,Sheet2!$C$5,IF(AR6<=Sheet2!$D$6,Sheet2!$C$6,IF(AR6<=Sheet2!$D$7,Sheet2!$C$7,IF(AR6<=Sheet2!$D$8,Sheet2!$C$8,IF(AR6<=Sheet2!$D$9,Sheet2!$C$9,IF(AR6<=Sheet2!$D$10,Sheet2!$C$10,IF(AR6<=Sheet2!$D$11,Sheet2!$C$11,0)))))))))) -> 150 | AT6: =AS6-V6 -> 90 | AY6: =AS6/H6 -> 12 | AZ6: =(AR6/H6*1000)*3.4 -> 272 | BA6: VRV-GF-01 | BB6: =IF(AR6<=Sheet2!$D$2,Sheet2!$B$2,IF(AR6<=Sheet2!$D$3,Sheet2!$B$3,IF(AR6<=Sheet2!$D$4,Sheet2!$B$4,IF(AR6<=Sheet2!$D$5,Sheet2!$B$5,IF(AR6<=Sheet2!$D$6,Sheet2!$B$6,IF(AR6<=Sheet2!$D$7,Sheet2!$B$7,IF(AR6<=Sheet2!$D$8,Sheet2!$B$8,IF(AR6<=Sheet2!$D$9,Sheet2!$B$9,IF(AR6<=Sheet2!$D$10,Sheet2!$B$10,IF(AR6<=Sheet2!$D$11,Sheet2!$B$11,0)))))))))) -> FXSQ20A
A7: Laundry Room | B7: 3 | C7: Group 6 | D7: GF-003 | E7: Sheet Washing Room | F7: غرفة غسيل الملاءات | G7: 11.2 | H7: =G7 -> 11.2 | I7: 1 | K7: =I7 -> 1 | L7: 0 | M7: 0 | N7: =VLOOKUP(A7,Data!A:B,2,FALSE) -> 0 | O7: =L7 -> 0 | P7: 26 | Q7: <60 | R7: =VLOOKUP(A7,Data!A:D,4,FALSE) -> 0 | S7: =VLOOKUP(A7,Data!A:C,3,FALSE) -> 0 | U7: =R7*I7+S7*G7 -> 0 | V7: 50 | Z7: =U7/0.85 -> 0 | AA7: 55 | AB7: -55 | AD7: =IF(V7+W7+AB7 > 0, "Positive", IF(V7-+W7+AB7 < 0, "Negative", "Neutral")) -> Negative | AE7: =ROUND(ABS((V7+AB7+W7+AC7)*3.6)/(G7*3),2) -> 0.54 | AF7: =AND(AE7>=0.3,AE7<=0.8) -> TRUE | AK7: =VLOOKUP(A7,Data!A:F,6,FALSE) -> 10 | AL7: =AK7*G7/1000 -> 0.112 | AM7: =AL7 -> 0.112 | AP7: 1 | AQ7: =AO7/AP7 -> 0 | AR7: 5.9 | AS7: =IF(AR7<=Sheet2!$D$2,Sheet2!$C$2,IF(AR7<=Sheet2!$D$3,Sheet2!$C$3,IF(AR7<=Sheet2!$D$4,Sheet2!$C$4,IF(AR7<=Sheet2!$D$5,Sheet2!$C$5,IF(AR7<=Sheet2!$D$6,Sheet2!$C$6,IF(AR7<=Sheet2!$D$7,Sheet2!$C$7,IF(AR7<=Sheet2!$D$8,Sheet2!$C$8,IF(AR7<=Sheet2!$D$9,Sheet2!$C$9,IF(AR7<=Sheet2!$D$10,Sheet2!$C$10,IF(AR7<=Sheet2!$D$11,Sheet2!$C$11,0)))))))))) -> 533 | AT7: =AS7-V7 -> 483 | AY7: =AS7/H7 -> 47.589286 | AZ7: =(AR7/H7*1000)*3.4 -> 1791.0714 | BA7: VRV-GF-01 | BB7: =IF(AR7<=Sheet2!$D$2,Sheet2!$B$2,IF(AR7<=Sheet2!$D$3,Sheet2!$B$3,IF(AR7<=Sheet2!$D$4,Sheet2!$B$4,IF(AR7<=Sheet2!$D$5,Sheet2!$B$5,IF(AR7<=Sheet2!$D$6,Sheet2!$B$6,IF(AR7<=Sheet2!$D$7,Sheet2!$B$7,IF(AR7<=Sheet2!$D$8,Sheet2!$B$8,IF(AR7<=Sheet2!$D$9,Sheet2!$B$9,IF(AR7<=Sheet2!$D$10,Sheet2!$B$10,IF(AR7<=Sheet2!$D$11,Sheet2!$B$11,0)))))))))) -> FXSQ100A
A8: Storage | B8: 4 | C8: Group 6 | D8: GF-004 | E8: Cleaning Supplies Storage | F8: مخزن مستلزمات تنظيف | G8: =2.5*2.4 -> 6 | H8: =G8 -> 6 | I8: 1 | K8: =I8 -> 1 | L8: 0 | M8: 0 | N8: =VLOOKUP(A8,Data!A:B,2,FALSE) -> 2 | O8: =L8 -> 0 | P8: 22 | Q8: <60 | R8: =VLOOKUP(A8,Data!A:D,4,FALSE) -> 0 | S8: =VLOOKUP(A8,Data!A:C,3,FALSE) -> 0 | U8: =R8*I8+S8*G8 -> 0 | V8: 12 | Z8: 10 | AA8: 25 | AB8: -15 | AD8: =IF(V8+W8+AB8 > 0, "Positive", IF(V8-+W8+AB8 < 0, "Negative", "Neutral")) -> Negative | AE8: =ROUND(ABS((V8+AB8+W8+AC8)*3.6)/(G8*3),2) -> 0.6 | AF8: =AND(AE8>=0.3,AE8<=0.8) -> TRUE | AK8: =VLOOKUP(A8,Data!A:F,6,FALSE) -> 10 | AL8: =AK8*G8/1000 -> 0.06 | AM8: =AL8 -> 0.06 | AP8: 1 | AQ8: =AO8/AP8 -> 0 | AR8: 0 | AS8: =IF(AR8<=Sheet2!$D$2,Sheet2!$C$2,IF(AR8<=Sheet2!$D$3,Sheet2!$C$3,IF(AR8<=Sheet2!$D$4,Sheet2!$C$4,IF(AR8<=Sheet2!$D$5,Sheet2!$C$5,IF(AR8<=Sheet2!$D$6,Sheet2!$C$6,IF(AR8<=Sheet2!$D$7,Sheet2!$C$7,IF(AR8<=Sheet2!$D$8,Sheet2!$C$8,IF(AR8<=Sheet2!$D$9,Sheet2!$C$9,IF(AR8<=Sheet2!$D$10,Sheet2!$C$10,IF(AR8<=Sheet2!$D$11,Sheet2!$C$11,0)))))))))) -> 150 | AT8: =AS8-V8 -> 138 | AY8: =AS8/H8 -> 25 | AZ8: =(AR8/H8*1000)*3.4 -> 0 | BA8: VRV-GF-01 | BB8: With Corridor GF-016
A9: Storage | B9: 5 | C9: Group 6 | D9: GF-005 | E9: Sanitizing Room | F9: غرفة تعقيم | G9: =2.5*2.4 -> 6 | H9: =G9 -> 6 | I9: 1 | K9: =I9 -> 1 | L9: 0 | M9: 0 | N9: =VLOOKUP(A9,Data!A:B,2,FALSE) -> 2 | O9: =L9 -> 0 | P9: 22 | Q9: <60 | R9: =VLOOKUP(A9,Data!A:D,4,FALSE) -> 0 | S9: =VLOOKUP(A9,Data!A:C,3,FALSE) -> 0 | U9: 10 | V9: 12 | Z9: 0 | AA9: 25 | AB9: -15 | AD9: =IF(V9+W9+AB9 > 0, "Positive", IF(V9-+W9+AB9 < 0, "Negative", "Neutral")) -> Negative | AE9: =ROUND(ABS((V9+AB9+W9+AC9)*3.6)/(G9*3),2) -> 0.6 | AF9: =AND(AE9>=0.3,AE9<=0.8) -> TRUE | AK9: =VLOOKUP(A9,Data!A:F,6,FALSE) -> 10 | AL9: =AK9*G9/1000 -> 0.06 | AM9: =AL9 -> 0.06 | AP9: 1 | AQ9: =AO9/AP9 -> 0 | AR9: 0 | AS9: =IF(AR9<=Sheet2!$D$2,Sheet2!$C$2,IF(AR9<=Sheet2!$D$3,Sheet2!$C$3,IF(AR9<=Sheet2!$D$4,Sheet2!$C$4,IF(AR9<=Sheet2!$D$5,Sheet2!$C$5,IF(AR9<=Sheet2!$D$6,Sheet2!$C$6,IF(AR9<=Sheet2!$D$7,Sheet2!$C$7,IF(AR9<=Sheet2!$D$8,Sheet2!$C$8,IF(AR9<=Sheet2!$D$9,Sheet2!$C$9,IF(AR9<=Sheet2!$D$10,Sheet2!$C$10,IF(AR9<=Sheet2!$D$11,Sheet2!$C$11,0)))))))))) -> 150 | AT9: =AS9-V9 -> 138 | AY9: =AS9/H9 -> 25 | AZ9: =(AR9/H9*1000)*3.4 -> 0 | BA9: VRV-GF-01 | BB9: With Corridor GF-016
A10: Storage | B10: 6 | C10: Group 6 | D10: GF-006 | E10: Preparation Supplies Storage | F10: مخزن مستلزمات اعداد | G10: =2.5*5 -> 12.5 | H10: =G10 -> 12.5 | I10: 1 | K10: =I10 -> 1 | L10: 0 | M10: 0 | N10: =VLOOKUP(A10,Data!A:B,2,FALSE) -> 2 | O10: =L10 -> 0 | P10: 22 | Q10: <60 | R10: =VLOOKUP(A10,Data!A:D,4,FALSE) -> 0 | S10: =VLOOKUP(A10,Data!A:C,3,FALSE) -> 0 | U10: =R10*I10+S10*G10 -> 0 | V10: 10 | Z10: 10 | AA10: 25 | AB10: -15 | AD10: =IF(V10+W10+AB10 > 0, "Positive", IF(V10-+W10+AB10 < 0, "Negative", "Neutral")) -> Negative | AE10: =ROUND(ABS((V10+AB10+W10+AC10)*3.6)/(G10*3),2) -> 0.48 | AF10: =AND(AE10>=0.3,AE10<=0.8) -> TRUE | AK10: =VLOOKUP(A10,Data!A:F,6,FALSE) -> 10 | AL10: =AK10*G10/1000 -> 0.125 | AM10: =AL10 -> 0.125 | AP10: 1 | AQ10: =AO10/AP10 -> 0 | AR10: 0 | AS10: =IF(AR10<=Sheet2!$D$2,Sheet2!$C$2,IF(AR10<=Sheet2!$D$3,Sheet2!$C$3,IF(AR10<=Sheet2!$D$4,Sheet2!$C$4,IF(AR10<=Sheet2!$D$5,Sheet2!$C$5,IF(AR10<=Sheet2!$D$6,Sheet2!$C$6,IF(AR10<=Sheet2!$D$7,Sheet2!$C$7,IF(AR10<=Sheet2!$D$8,Sheet2!$C$8,IF(AR10<=Sheet2!$D$9,Sheet2!$C$9,IF(AR10<=Sheet2!$D$10,Sheet2!$C$10,IF(AR10<=Sheet2!$D$11,Sheet2!$C$11,0)))))))))) -> 150 | AT10: =AS10-V10 -> 140 | AY10: =AS10/H10 -> 12 | AZ10: =(AR10/H10*1000)*3.4 -> 0 | BA10: VRV-GF-01 | BB10: With Corridor GF-016
A11: Prep and Shrouding area | B11: 7 | C11: Group 6 | D11: GF-007 | E11: Women's Viewing Room | F11: غرفة مشاهدة نساء | G11: =4*5 -> 20 | H11: =G11 -> 20 | I11: 12 | K11: =I11 -> 12 | L11: 0 | M11: 0 | N11: =VLOOKUP(A11,Data!A:B,2,FALSE) -> 0 | O11: =L11 -> 0 | P11: 26 | Q11: <60 | R11: =VLOOKUP(A11,Data!A:D,4,FALSE) -> 0 | S11: =VLOOKUP(A11,Data!A:C,3,FALSE) -> 0 | T11: 2 | U11: =T11*G11*3/3.6 -> 33.333333 | V11: =CEILING(U11,5) -> 35 | Z11: =U11/0.85 -> 39.215686 | AA11: 40 | AB11: -40 | AD11: =IF(V11+W11+AB11 > 0, "Positive", IF(V11-+W11+AB11 < 0, "Negative", "Neutral")) -> Negative | AE11: =ROUND(ABS((V11+AB11+W11+AC11)*3.6)/(G11*3),2) -> 0.3 | AF11: =AND(AE11>=0.3,AE11<=0.8) -> TRUE | AK11: =VLOOKUP(A11,Data!A:F,6,FALSE) -> 10 | AL11: =AK11*G11/1000 -> 0.2 | AM11: =AL11 -> 0.2 | AP11: 1 | AQ11: =AO11/AP11 -> 0 | AR11: 1.7 | AS11: =IF(AR11<=Sheet2!$D$2,Sheet2!$C$2,IF(AR11<=Sheet2!$D$3,Sheet2!$C$3,IF(AR11<=Sheet2!$D$4,Sheet2!$C$4,IF(AR11<=Sheet2!$D$5,Sheet2!$C$5,IF(AR11<=Sheet2!$D$6,Sheet2!$C$6,IF(AR11<=Sheet2!$D$7,Sheet2!$C$7,IF(AR11<=Sheet2!$D$8,Sheet2!$C$8,IF(AR11<=Sheet2!$D$9,Sheet2!$C$9,IF(AR11<=Sheet2!$D$10,Sheet2!$C$10,IF(AR11<=Sheet2!$D$11,Sheet2!$C$11,0)))))))))) -> 150 | AT11: =AS11-V11 -> 115 | AY11: =AS11/H11 -> 7.5 | AZ11: =(AR11/H11*1000)*3.4 -> 289 | BA11: VRV-GF-01 | BB11: =IF(AR11<=Sheet2!$D$2,Sheet2!$B$2,IF(AR11<=Sheet2!$D$3,Sheet2!$B$3,IF(AR11<=Sheet2!$D$4,Sheet2!$B$4,IF(AR11<=Sheet2!$D$5,Sheet2!$B$5,IF(AR11<=Sheet2!$D$6,Sheet2!$B$6,IF(AR11<=Sheet2!$D$7,Sheet2!$B$7,IF(AR11<=Sheet2!$D$8,Sheet2!$B$8,IF(AR11<=Sheet2!$D$9,Sheet2!$B$9,IF(AR11<=Sheet2!$D$10,Sheet2!$B$10,IF(AR11<=Sheet2!$D$11,Sheet2!$B$11,0)))))))))) -> FXSQ25A
A12: Prep and Shrouding area | B12: 8 | C12: Group 6 | D12: GF-008 | E12: Women's Viewing Room | F12: غرفة مشاهدة نساء | G12: =4*5 -> 20 | H12: =G12 -> 20 | I12: 12 | K12: =I12 -> 12 | L12: 0 | M12: 0 | N12: =VLOOKUP(A12,Data!A:B,2,FALSE) -> 0 | O12: =L12 -> 0 | P12: 22 | Q12: <60 | R12: =VLOOKUP(A12,Data!A:D,4,FALSE) -> 0 | S12: =VLOOKUP(A12,Data!A:C,3,FALSE) -> 0 | T12: 2 | U12: =T12*G12*3/3.6 -> 33.333333 | V12: =CEILING(U12,5) -> 35 | Z12: =U12/0.85 -> 39.215686 | AA12: 40 | AB12: -40 | AD12: =IF(V12+W12+AB12 > 0, "Positive", IF(V12-+W12+AB12 < 0, "Negative", "Neutral")) -> Negative | AE12: =ROUND(ABS((V12+AB12+W12+AC12)*3.6)/(G12*3),2) -> 0.3 | AF12: =AND(AE12>=0.3,AE12<=0.8) -> TRUE | AK12: =VLOOKUP(A12,Data!A:F,6,FALSE) -> 10 | AL12: =AK12*G12/1000 -> 0.2 | AM12: =AL12 -> 0.2 | AP12: 1 | AQ12: =AO12/AP12 -> 0 | AR12: 1.7 | AS12: =IF(AR12<=Sheet2!$D$2,Sheet2!$C$2,IF(AR12<=Sheet2!$D$3,Sheet2!$C$3,IF(AR12<=Sheet2!$D$4,Sheet2!$C$4,IF(AR12<=Sheet2!$D$5,Sheet2!$C$5,IF(AR12<=Sheet2!$D$6,Sheet2!$C$6,IF(AR12<=Sheet2!$D$7,Sheet2!$C$7,IF(AR12<=Sheet2!$D$8,Sheet2!$C$8,IF(AR12<=Sheet2!$D$9,Sheet2!$C$9,IF(AR12<=Sheet2!$D$10,Sheet2!$C$10,IF(AR12<=Sheet2!$D$11,Sheet2!$C$11,0)))))))))) -> 150 | AT12: =AS12-V12 -> 115 | AY12: =AS12/H12 -> 7.5 | AZ12: =(AR12/H12*1000)*3.4 -> 289 | BA12: VRV-GF-01 | BB12: =IF(AR12<=Sheet2!$D$2,Sheet2!$B$2,IF(AR12<=Sheet2!$D$3,Sheet2!$B$3,IF(AR12<=Sheet2!$D$4,Sheet2!$B$4,IF(AR12<=Sheet2!$D$5,Sheet2!$B$5,IF(AR12<=Sheet2!$D$6,Sheet2!$B$6,IF(AR12<=Sheet2!$D$7,Sheet2!$B$7,IF(AR12<=Sheet2!$D$8,Sheet2!$B$8,IF(AR12<=Sheet2!$D$9,Sheet2!$B$9,IF(AR12<=Sheet2!$D$10,Sheet2!$B$10,IF(AR12<=Sheet2!$D$11,Sheet2!$B$11,0)))))))))) -> FXSQ25A
A13: Prep and Shrouding area | B13: 9 | C13: Group 6 | D13: GF-009 | E13: Women's Viewing Room | F13: غرفة مشاهدة نساء | G13: =4*5 -> 20 | H13: =G13 -> 20 | I13: 12 | K13: =I13 -> 12 | L13: 0 | M13: 0 | N13: =VLOOKUP(A13,Data!A:B,2,FALSE) -> 0 | O13: =L13 -> 0 | P13: 22 | Q13: <60 | R13: =VLOOKUP(A13,Data!A:D,4,FALSE) -> 0 | S13: =VLOOKUP(A13,Data!A:C,3,FALSE) -> 0 | T13: 2 | U13: =T13*G13*3/3.6 -> 33.333333 | V13: =CEILING(U13,5) -> 35 | Z13: =U13/0.85 -> 39.215686 | AA13: 40 | AB13: -40 | AD13: =IF(V13+W13+AB13 > 0, "Positive", IF(V13-+W13+AB13 < 0, "Negative", "Neutral")) -> Negative | AE13: =ROUND(ABS((V13+AB13+W13+AC13)*3.6)/(G13*3),2) -> 0.3 | AF13: =AND(AE13>=0.3,AE13<=0.8) -> TRUE | AK13: =VLOOKUP(A13,Data!A:F,6,FALSE) -> 10 | AL13: =AK13*G13/1000 -> 0.2 | AM13: =AL13 -> 0.2 | AP13: 1 | AQ13: =AO13/AP13 -> 0 | AR13: 1.7 | AS13: =IF(AR13<=Sheet2!$D$2,Sheet2!$C$2,IF(AR13<=Sheet2!$D$3,Sheet2!$C$3,IF(AR13<=Sheet2!$D$4,Sheet2!$C$4,IF(AR13<=Sheet2!$D$5,Sheet2!$C$5,IF(AR13<=Sheet2!$D$6,Sheet2!$C$6,IF(AR13<=Sheet2!$D$7,Sheet2!$C$7,IF(AR13<=Sheet2!$D$8,Sheet2!$C$8,IF(AR13<=Sheet2!$D$9,Sheet2!$C$9,IF(AR13<=Sheet2!$D$10,Sheet2!$C$10,IF(AR13<=Sheet2!$D$11,Sheet2!$C$11,0)))))))))) -> 150 | AT13: =AS13-V13 -> 115 | AY13: =AS13/H13 -> 7.5 | AZ13: =(AR13/H13*1000)*3.4 -> 289 | BA13: VRV-GF-01 | BB13: =IF(AR13<=Sheet2!$D$2,Sheet2!$B$2,IF(AR13<=Sheet2!$D$3,Sheet2!$B$3,IF(AR13<=Sheet2!$D$4,Sheet2!$B$4,IF(AR13<=Sheet2!$D$5,Sheet2!$B$5,IF(AR13<=Sheet2!$D$6,Sheet2!$B$6,IF(AR13<=Sheet2!$D$7,Sheet2!$B$7,IF(AR13<=Sheet2!$D$8,Sheet2!$B$8,IF(AR13<=Sheet2!$D$9,Sheet2!$B$9,IF(AR13<=Sheet2!$D$10,Sheet2!$B$10,IF(AR13<=Sheet2!$D$11,Sheet2!$B$11,0)))))))))) -> FXSQ25A
A14: bathroom | B14: 10 | C14: Group 6 | D14: GF-010 | E14: Women's Rest Room | F14: دورة مياه نساء | G14: =5*4.2 -> 21 | H14: =G14 -> 21 | I14: 4 | K14: 0 | L14: 0 | M14: 0 | N14: =VLOOKUP(A14,Data!A:B,2,FALSE) -> 0 | O14: =L14 -> 0 | P14: 22 | Q14: <60 | R14: =VLOOKUP(A14,Data!A:D,4,FALSE) -> 0 | S14: =VLOOKUP(A14,Data!A:C,3,FALSE) -> 0 | U14: =AA14*0.85 -> 106.25 | V14: 0 | W14: 115 | X14: 25 | Y14: 5 | Z14: =Y14*X14 -> 125 | AA14: 125 | AB14: -125 | AD14: =IF(V14+W14+AB14 > 0, "Positive", IF(V14-+W14+AB14 < 0, "Negative", "Neutral")) -> Negative | AE14: =ROUND(ABS((V14+AB14+W14+AC14)*3.6)/(G14*3),2) -> 0.57 | AF14: =AND(AE14>=0.3,AE14<=0.8) -> TRUE | AK14: =VLOOKUP(A14,Data!A:F,6,FALSE) -> 10 | AL14: =AK14*G14/1000 -> 0.21 | AM14: =AL14 -> 0.21 | AP14: 1 | AQ14: =AO14/AP14 -> 0 | AR14: 2.8 | AS14: =IF(AR14<=Sheet2!$D$2,Sheet2!$C$2,IF(AR14<=Sheet2!$D$3,Sheet2!$C$3,IF(AR14<=Sheet2!$D$4,Sheet2!$C$4,IF(AR14<=Sheet2!$D$5,Sheet2!$C$5,IF(AR14<=Sheet2!$D$6,Sheet2!$C$6,IF(AR14<=Sheet2!$D$7,Sheet2!$C$7,IF(AR14<=Sheet2!$D$8,Sheet2!$C$8,IF(AR14<=Sheet2!$D$9,Sheet2!$C$9,IF(AR14<=Sheet2!$D$10,Sheet2!$C$10,IF(AR14<=Sheet2!$D$11,Sheet2!$C$11,0)))))))))) -> 250 | AT14: =AS14-V14 -> 250 | AY14: =AS14/H14 -> 11.904762 | AZ14: =(AR14/H14*1000)*3.4 -> 453.33333 | BA14: VRV-GF-01 | BB14: with GF-016 Waiting Room
A15: Storage | B15: 11 | C15: Group 6 | D15: GF-011 | E15: Cold Room | F15: غرفة تبريد | G15: =5*5.4 -> 27 | H15: =G15 -> 27 | I15: 1 | K15: =I15 -> 1 | L15: 0 | M15: 0 | N15: =VLOOKUP(A15,Data!A:B,2,FALSE) -> 2 | O15: =L15 -> 0 | P15: 22 | Q15: <60 | R15: =VLOOKUP(A15,Data!A:D,4,FALSE) -> 0 | S15: =VLOOKUP(A15,Data!A:C,3,FALSE) -> 0 | T15: 2 | U15: =T15*G15*3/3.6 -> 45 | V15: 45 | Z15: =U15/0.85 -> 52.941176 | AA15: 55 | AB15: -55 | AD15: =IF(V15+W15+AB15 > 0, "Positive", IF(V15-+W15+AB15 < 0, "Negative", "Neutral")) -> Negative | AE15: =ROUND(ABS((V15+AB15+W15+AC15)*3.6)/(G15*3),2) -> 0.44 | AF15: =AND(AE15>=0.3,AE15<=0.8) -> TRUE | AK15: =VLOOKUP(A15,Data!A:F,6,FALSE) -> 10 | AL15: =AK15*G15/1000 -> 0.27 | AM15: =AL15 -> 0.27 | AP15: 1 | AQ15: =AO15/AP15 -> 0 | AR15: 1.9 | AS15: =IF(AR15<=Sheet2!$D$2,Sheet2!$C$2,IF(AR15<=Sheet2!$D$3,Sheet2!$C$3,IF(AR15<=Sheet2!$D$4,Sheet2!$C$4,IF(AR15<=Sheet2!$D$5,Sheet2!$C$5,IF(AR15<=Sheet2!$D$6,Sheet2!$C$6,IF(AR15<=Sheet2!$D$7,Sheet2!$C$7,IF(AR15<=Sheet2!$D$8,Sheet2!$C$8,IF(AR15<=Sheet2!$D$9,Sheet2!$C$9,IF(AR15<=Sheet2!$D$10,Sheet2!$C$10,IF(AR15<=Sheet2!$D$11,Sheet2!$C$11,0)))))))))) -> 158 | AT15: =AS15-V15 -> 113 | AY15: =AS15/H15 -> 5.8518519 | AZ15: =(AR15/H15*1000)*3.4 -> 239.25926 | BA15: VRV-GF-01 | BB15: =IF(AR15<=Sheet2!$D$2,Sheet2!$B$2,IF(AR15<=Sheet2!$D$3,Sheet2!$B$3,IF(AR15<=Sheet2!$D$4,Sheet2!$B$4,IF(AR15<=Sheet2!$D$5,Sheet2!$B$5,IF(AR15<=Sheet2!$D$6,Sheet2!$B$6,IF(AR15<=Sheet2!$D$7,Sheet2!$B$7,IF(AR15<=Sheet2!$D$8,Sheet2!$B$8,IF(AR15<=Sheet2!$D$9,Sheet2!$B$9,IF(AR15<=Sheet2!$D$10,Sheet2!$B$10,IF(AR15<=Sheet2!$D$11,Sheet2!$B$11,0)))))))))) -> FXSQ32A
A16: Prep and Shrouding area | B16: 12 | C16: Group 6 | D16: GF-012 | E16: Preparation and Shrouding Room | F16: غرفة تجهيز وتكفين | G16: =5*4 -> 20 | H16: =G16 -> 20 | I16: 2 | K16: =I16 -> 2 | L16: 0 | M16: 0 | N16: =VLOOKUP(A16,Data!A:B,2,FALSE) -> 0 | O16: =L16 -> 0 | P16: 22 | Q16: <60 | R16: =VLOOKUP(A16,Data!A:D,4,FALSE) -> 0 | S16: =VLOOKUP(A16,Data!A:C,3,FALSE) -> 0 | T16: 2 | U16: =T16*G16*3/3.6 -> 33.333333 | V16: =CEILING(U16,5) -> 35 | Z16: =U16/0.85 -> 39.215686 | AA16: =CEILING(Z16,1) -> 40 | AB16: =(CEILING(AA16,1))*-1 -> -40 | AD16: =IF(V16+W16+AB16 > 0, "Positive", IF(V16-+W16+AB16 < 0, "Negative", "Neutral")) -> Negative | AE16: =ROUND(ABS((V16+AB16+W16+AC16)*3.6)/(G16*3),2) -> 0.3 | AF16: =AND(AE16>=0.3,AE16<=0.8) -> TRUE | AK16: =VLOOKUP(A16,Data!A:F,6,FALSE) -> 10 | AL16: =AK16*G16/1000 -> 0.2 | AM16: =AL16 -> 0.2 | AP16: 1 | AQ16: =AO16/AP16 -> 0 | AR16: 2.4 | AS16: =IF(AR16<=Sheet2!$D$2,Sheet2!$C$2,IF(AR16<=Sheet2!$D$3,Sheet2!$C$3,IF(AR16<=Sheet2!$D$4,Sheet2!$C$4,IF(AR16<=Sheet2!$D$5,Sheet2!$C$5,IF(AR16<=Sheet2!$D$6,Sheet2!$C$6,IF(AR16<=Sheet2!$D$7,Sheet2!$C$7,IF(AR16<=Sheet2!$D$8,Sheet2!$C$8,IF(AR16<=Sheet2!$D$9,Sheet2!$C$9,IF(AR16<=Sheet2!$D$10,Sheet2!$C$10,IF(AR16<=Sheet2!$D$11,Sheet2!$C$11,0)))))))))) -> 158 | AT16: =AS16-V16 -> 123 | AY16: =AS16/H16 -> 7.9 | AZ16: =(AR16/H16*1000)*3.4 -> 408 | BA16: VRV-GF-01 | BB16: =IF(AR16<=Sheet2!$D$2,Sheet2!$B$2,IF(AR16<=Sheet2!$D$3,Sheet2!$B$3,IF(AR16<=Sheet2!$D$4,Sheet2!$B$4,IF(AR16<=Sheet2!$D$5,Sheet2!$B$5,IF(AR16<=Sheet2!$D$6,Sheet2!$B$6,IF(AR16<=Sheet2!$D$7,Sheet2!$B$7,IF(AR16<=Sheet2!$D$8,Sheet2!$B$8,IF(AR16<=Sheet2!$D$9,Sheet2!$B$9,IF(AR16<=Sheet2!$D$10,Sheet2!$B$10,IF(AR16<=Sheet2!$D$11,Sheet2!$B$11,0)))))))))) -> FXSQ32A
A17: Prep and Shrouding area | B17: 13 | C17: Group 6 | D17: GF-013 | E17: Preparation and Shrouding Room | F17: غرفة تجهيز وتكفين | G17: =5*4 -> 20 | H17: =G17 -> 20 | I17: 2 | K17: =I17 -> 2 | L17: 0 | M17: 0 | N17: =VLOOKUP(A17,Data!A:B,2,FALSE) -> 0 | O17: =L17 -> 0 | P17: 22 | Q17: <60 | R17: =VLOOKUP(A17,Data!A:D,4,FALSE) -> 0 | S17: =VLOOKUP(A17,Data!A:C,3,FALSE) -> 0 | T17: 2 | U17: =T17*G17*3/3.6 -> 33.333333 | V17: =CEILING(U17,5) -> 35 | Z17: =U17/0.85 -> 39.215686 | AA17: =CEILING(Z17,1) -> 40 | AB17: =(CEILING(AA17,1))*-1 -> -40 | AD17: =IF(V17+W17+AB17 > 0, "Positive", IF(V17-+W17+AB17 < 0, "Negative", "Neutral")) -> Negative | AE17: =ROUND(ABS((V17+AB17+W17+AC17)*3.6)/(G17*3),2) -> 0.3 | AF17: =AND(AE17>=0.3,AE17<=0.8) -> TRUE | AK17: =VLOOKUP(A17,Data!A:F,6,FALSE) -> 10 | AL17: =AK17*G17/1000 -> 0.2 | AM17: =AL17 -> 0.2 | AP17: 1 | AQ17: =AO17/AP17 -> 0 | AR17: 2.4 | AS17: =IF(AR17<=Sheet2!$D$2,Sheet2!$C$2,IF(AR17<=Sheet2!$D$3,Sheet2!$C$3,IF(AR17<=Sheet2!$D$4,Sheet2!$C$4,IF(AR17<=Sheet2!$D$5,Sheet2!$C$5,IF(AR17<=Sheet2!$D$6,Sheet2!$C$6,IF(AR17<=Sheet2!$D$7,Sheet2!$C$7,IF(AR17<=Sheet2!$D$8,Sheet2!$C$8,IF(AR17<=Sheet2!$D$9,Sheet2!$C$9,IF(AR17<=Sheet2!$D$10,Sheet2!$C$10,IF(AR17<=Sheet2!$D$11,Sheet2!$C$11,0)))))))))) -> 158 | AT17: =AS17-V17 -> 123 | AY17: =AS17/H17 -> 7.9 | AZ17: =(AR17/H17*1000)*3.4 -> 408 | BA17: VRV-GF-01 | BB17: =IF(AR17<=Sheet2!$D$2,Sheet2!$B$2,IF(AR17<=Sheet2!$D$3,Sheet2!$B$3,IF(AR17<=Sheet2!$D$4,Sheet2!$B$4,IF(AR17<=Sheet2!$D$5,Sheet2!$B$5,IF(AR17<=Sheet2!$D$6,Sheet2!$B$6,IF(AR17<=Sheet2!$D$7,Sheet2!$B$7,IF(AR17<=Sheet2!$D$8,Sheet2!$B$8,IF(AR17<=Sheet2!$D$9,Sheet2!$B$9,IF(AR17<=Sheet2!$D$10,Sheet2!$B$10,IF(AR17<=Sheet2!$D$11,Sheet2!$B$11,0)))))))))) -> FXSQ32A
A18: Prep and Shrouding area | B18: 14 | C18: Group 6 | D18: GF-014 | E18: Preparation and Shrouding Room | F18: غرفة تجهيز وتكفين | G18: =5*4 -> 20 | H18: =G18 -> 20 | I18: 2 | K18: =I18 -> 2 | L18: 0 | M18: 0 | N18: =VLOOKUP(A18,Data!A:B,2,FALSE) -> 0 | O18: =L18 -> 0 | P18: 22 | Q18: <60 | R18: =VLOOKUP(A18,Data!A:D,4,FALSE) -> 0 | S18: =VLOOKUP(A18,Data!A:C,3,FALSE) -> 0 | T18: 2 | U18: =T18*G18*3/3.6 -> 33.333333 | V18: =CEILING(U18,5) -> 35 | Z18: =U18/0.85 -> 39.215686 | AA18: =CEILING(Z18,1) -> 40 | AB18: =(CEILING(AA18,1))*-1 -> -40 | AD18: =IF(V18+W18+AB18 > 0, "Positive", IF(V18-+W18+AB18 < 0, "Negative", "Neutral")) -> Negative | AE18: =ROUND(ABS((V18+AB18+W18+AC18)*3.6)/(G18*3),2) -> 0.3 | AF18: =AND(AE18>=0.3,AE18<=0.8) -> TRUE | AK18: =VLOOKUP(A18,Data!A:F,6,FALSE) -> 10 | AL18: =AK18*G18/1000 -> 0.2 | AM18: =AL18 -> 0.2 | AP18: 1 | AQ18: =AO18/AP18 -> 0 | AR18: 2.4 | AS18: =IF(AR18<=Sheet2!$D$2,Sheet2!$C$2,IF(AR18<=Sheet2!$D$3,Sheet2!$C$3,IF(AR18<=Sheet2!$D$4,Sheet2!$C$4,IF(AR18<=Sheet2!$D$5,Sheet2!$C$5,IF(AR18<=Sheet2!$D$6,Sheet2!$C$6,IF(AR18<=Sheet2!$D$7,Sheet2!$C$7,IF(AR18<=Sheet2!$D$8,Sheet2!$C$8,IF(AR18<=Sheet2!$D$9,Sheet2!$C$9,IF(AR18<=Sheet2!$D$10,Sheet2!$C$10,IF(AR18<=Sheet2!$D$11,Sheet2!$C$11,0)))))))))) -> 158 | AT18: =AS18-V18 -> 123 | AY18: =AS18/H18 -> 7.9 | AZ18: =(AR18/H18*1000)*3.4 -> 408 | BA18: VRV-GF-01 | BB18: =IF(AR18<=Sheet2!$D$2,Sheet2!$B$2,IF(AR18<=Sheet2!$D$3,Sheet2!$B$3,IF(AR18<=Sheet2!$D$4,Sheet2!$B$4,IF(AR18<=Sheet2!$D$5,Sheet2!$B$5,IF(AR18<=Sheet2!$D$6,Sheet2!$B$6,IF(AR18<=Sheet2!$D$7,Sheet2!$B$7,IF(AR18<=Sheet2!$D$8,Sheet2!$B$8,IF(AR18<=Sheet2!$D$9,Sheet2!$B$9,IF(AR18<=Sheet2!$D$10,Sheet2!$B$10,IF(AR18<=Sheet2!$D$11,Sheet2!$B$11,0)))))))))) -> FXSQ32A
A19: Prep and Shrouding area | B19: 15 | C19: Group 6 | D19: GF-015 | E19: Preparation and Shrouding Room | F19: غرفة تجهيز وتكفين | G19: =5*4 -> 20 | H19: =G19 -> 20 | I19: 2 | K19: =I19 -> 2 | L19: 0 | M19: 0 | N19: =VLOOKUP(A19,Data!A:B,2,FALSE) -> 0 | O19: =L19 -> 0 | P19: 22 | Q19: <60 | R19: =VLOOKUP(A19,Data!A:D,4,FALSE) -> 0 | S19: =VLOOKUP(A19,Data!A:C,3,FALSE) -> 0 | T19: 2 | U19: =T19*G19*3/3.6 -> 33.333333 | V19: =CEILING(U19,5) -> 35 | Z19: =U19/0.85 -> 39.215686 | AA19: =CEILING(Z19,1) -> 40 | AB19: =(CEILING(AA19,1))*-1 -> -40 | AD19: =IF(V19+W19+AB19 > 0, "Positive", IF(V19-+W19+AB19 < 0, "Negative", "Neutral")) -> Negative | AE19: =ROUND(ABS((V19+AB19+W19+AC19)*3.6)/(G19*3),2) -> 0.3 | AF19: =AND(AE19>=0.3,AE19<=0.8) -> TRUE | AK19: =VLOOKUP(A19,Data!A:F,6,FALSE) -> 10 | AL19: =AK19*G19/1000 -> 0.2 | AM19: =AL19 -> 0.2 | AP19: 1 | AQ19: =AO19/AP19 -> 0 | AR19: 2.4 | AS19: =IF(AR19<=Sheet2!$D$2,Sheet2!$C$2,IF(AR19<=Sheet2!$D$3,Sheet2!$C$3,IF(AR19<=Sheet2!$D$4,Sheet2!$C$4,IF(AR19<=Sheet2!$D$5,Sheet2!$C$5,IF(AR19<=Sheet2!$D$6,Sheet2!$C$6,IF(AR19<=Sheet2!$D$7,Sheet2!$C$7,IF(AR19<=Sheet2!$D$8,Sheet2!$C$8,IF(AR19<=Sheet2!$D$9,Sheet2!$C$9,IF(AR19<=Sheet2!$D$10,Sheet2!$C$10,IF(AR19<=Sheet2!$D$11,Sheet2!$C$11,0)))))))))) -> 158 | AT19: =AS19-V19 -> 123 | AY19: =AS19/H19 -> 7.9 | AZ19: =(AR19/H19*1000)*3.4 -> 408 | BA19: VRV-GF-01 | BB19: =IF(AR19<=Sheet2!$D$2,Sheet2!$B$2,IF(AR19<=Sheet2!$D$3,Sheet2!$B$3,IF(AR19<=Sheet2!$D$4,Sheet2!$B$4,IF(AR19<=Sheet2!$D$5,Sheet2!$B$5,IF(AR19<=Sheet2!$D$6,Sheet2!$B$6,IF(AR19<=Sheet2!$D$7,Sheet2!$B$7,IF(AR19<=Sheet2!$D$8,Sheet2!$B$8,IF(AR19<=Sheet2!$D$9,Sheet2!$B$9,IF(AR19<=Sheet2!$D$10,Sheet2!$B$10,IF(AR19<=Sheet2!$D$11,Sheet2!$B$11,0)))))))))) -> FXSQ32A
A20: Waiting Area | B20: 16 | C20: Group 6 | D20: GF-016 | E20: Waiting Room | F20: صالة انتظار | G20: 98 | H20: =G20 -> 98 | I20: 9 | K20: =I20 -> 9 | L20: 0 | M20: 0 | N20: =VLOOKUP(A20,Data!A:B,2,FALSE) -> 50 | O20: =L20 -> 0 | P20: 22 | Q20: <60 | R20: =VLOOKUP(A20,Data!A:D,4,FALSE) -> 3.8 | S20: =VLOOKUP(A20,Data!A:C,3,FALSE) -> 0.3 | U20: =R20*I20+S20*G20 -> 63.6 | V20: 200 | W20: -115 | Z20: =0.85*V20 -> 170 | AB20: 0 | AD20: =IF(V20+W20+AB20 > 0, "Positive", IF(V20-+W20+AB20 < 0, "Negative", "Neutral")) -> Positive | AE20: =ROUND(ABS((V20+AB20+W20+AC20)*3.6)/(G20*3),2) -> 1.04 | AF20: =AND(AE20>=0.3,AE20<=0.8) -> FALSE | AK20: =VLOOKUP(A20,Data!A:F,6,FALSE) -> 10 | AL20: =AK20*G20/1000 -> 0.98 | AM20: =AL20 -> 0.98 | AP20: 2 | AQ20: =AO20/AP20 -> 0 | AR20: 3.9 | AS20: =IF(AR20<=Sheet2!$D$2,Sheet2!$C$2,IF(AR20<=Sheet2!$D$3,Sheet2!$C$3,IF(AR20<=Sheet2!$D$4,Sheet2!$C$4,IF(AR20<=Sheet2!$D$5,Sheet2!$C$5,IF(AR20<=Sheet2!$D$6,Sheet2!$C$6,IF(AR20<=Sheet2!$D$7,Sheet2!$C$7,IF(AR20<=Sheet2!$D$8,Sheet2!$C$8,IF(AR20<=Sheet2!$D$9,Sheet2!$C$9,IF(AR20<=Sheet2!$D$10,Sheet2!$C$10,IF(AR20<=Sheet2!$D$11,Sheet2!$C$11,0)))))))))) -> 350 | AT20: =AS20-V20 -> 150 | AY20: =AS20/H20 -> 3.5714286 | AZ20: =(AR20/H20*1000)*3.4 -> 135.30612 | BA20: VRV-GF-Common Areas | BB20: =IF(AR20<=Sheet2!$D$2,Sheet2!$B$2,IF(AR20<=Sheet2!$D$3,Sheet2!$B$3,IF(AR20<=Sheet2!$D$4,Sheet2!$B$4,IF(AR20<=Sheet2!$D$5,Sheet2!$B$5,IF(AR20<=Sheet2!$D$6,Sheet2!$B$6,IF(AR20<=Sheet2!$D$7,Sheet2!$B$7,IF(AR20<=Sheet2!$D$8,Sheet2!$B$8,IF(AR20<=Sheet2!$D$9,Sheet2!$B$9,IF(AR20<=Sheet2!$D$10,Sheet2!$B$10,IF(AR20<=Sheet2!$D$11,Sheet2!$B$11,0)))))))))) -> FXSQ63A
A21: Office | B21: 17 | C21: Group 10 | D21: GF-017 | E21: First Aid Medical Care Room | F21: غرفة رعاية طبية اسعافات اولية | G21: =4*3 -> 12 | H21: =G21 -> 12 | I21: 2 | K21: =I21 -> 2 | L21: 0 | M21: 0 | N21: =VLOOKUP(A21,Data!A:B,2,FALSE) -> 5 | O21: =L21 -> 0 | P21: 22 | Q21: <60 | R21: =VLOOKUP(A21,Data!A:D,4,FALSE) -> 2.5 | S21: =VLOOKUP(A21,Data!A:C,3,FALSE) -> 0.3 | U21: =R21*I21+S21*G21 -> 8.6 | V21: 30 | Z21: =0.85*V21 -> 25.5 | AA21: =CEILING(Z21,1) -> 26 | AC21: -25 | AD21: =IF(V21+W21+AB21 > 0, "Positive", IF(V21-+W21+AB21 < 0, "Negative", "Neutral")) -> Positive | AE21: =ROUND(ABS((V21+AB21+W21+AC21)*3.6)/(G21*3),2) -> 0.5 | AF21: =AND(AE21>=0.3,AE21<=0.8) -> TRUE | AK21: =VLOOKUP(A21,Data!A:F,6,FALSE) -> 10 | AL21: =AK21*G21/1000 -> 0.12 | AM21: =AL21 -> 0.12 | AP21: 1 | AQ21: =AO21/AP21 -> 0 | AR21: 2.1 | AS21: =IF(AR21<=Sheet2!$D$2,Sheet2!$C$2,IF(AR21<=Sheet2!$D$3,Sheet2!$C$3,IF(AR21<=Sheet2!$D$4,Sheet2!$C$4,IF(AR21<=Sheet2!$D$5,Sheet2!$C$5,IF(AR21<=Sheet2!$D$6,Sheet2!$C$6,IF(AR21<=Sheet2!$D$7,Sheet2!$C$7,IF(AR21<=Sheet2!$D$8,Sheet2!$C$8,IF(AR21<=Sheet2!$D$9,Sheet2!$C$9,IF(AR21<=Sheet2!$D$10,Sheet2!$C$10,IF(AR21<=Sheet2!$D$11,Sheet2!$C$11,0)))))))))) -> 158 | AT21: =AS21-V21 -> 128 | AY21: =AS21/H21 -> 13.166667 | AZ21: =(AR21/H21*1000)*3.4 -> 595 | BA21: VRV-GF-01 | BB21: =IF(AR21<=Sheet2!$D$2,Sheet2!$B$2,IF(AR21<=Sheet2!$D$3,Sheet2!$B$3,IF(AR21<=Sheet2!$D$4,Sheet2!$B$4,IF(AR21<=Sheet2!$D$5,Sheet2!$B$5,IF(AR21<=Sheet2!$D$6,Sheet2!$B$6,IF(AR21<=Sheet2!$D$7,Sheet2!$B$7,IF(AR21<=Sheet2!$D$8,Sheet2!$B$8,IF(AR21<=Sheet2!$D$9,Sheet2!$B$9,IF(AR21<=Sheet2!$D$10,Sheet2!$B$10,IF(AR21<=Sheet2!$D$11,Sheet2!$B$11,0)))))))))) -> FXSQ32A
A22: Reception | B22: 18 | C22: Group 10 | D22: GF-018 | E22: Reception | F22: مكتب استقبال | G22: =13.6*16.4-124 -> 99.04 | H22: =G22 -> 99.04 | I22: 30 | K22: =I22 -> 30 | L22: 0 | M22: 0 | N22: =VLOOKUP(A22,Data!A:B,2,FALSE) -> 30 | O22: =L22 -> 0 | P22: 22 | Q22: <60 | R22: =VLOOKUP(A22,Data!A:D,4,FALSE) -> 2.5 | S22: =VLOOKUP(A22,Data!A:C,3,FALSE) -> 0.3 | U22: =R22*I22+S22*G22 -> 104.712 | V22: =CEILING(U22,5) -> 105 | Z22: =0.85*V22 -> 89.25 | AA22: =CEILING(Z22,1) -> 90 | AC22: -70 | AD22: =IF(V22+W22+AB22 > 0, "Positive", IF(V22-+W22+AB22 < 0, "Negative", "Neutral")) -> Positive | AE22: =ROUND(ABS((V22+AB22+W22+AC22)*3.6)/(G22*3),2) -> 0.42 | AF22: =AND(AE22>=0.3,AE22<=0.8) -> TRUE | AK22: =VLOOKUP(A22,Data!A:F,6,FALSE) -> 10 | AL22: =AK22*G22/1000 -> 0.9904 | AM22: =AL22 -> 0.9904 | AP22: 1 | AQ22: =AO22/AP22 -> 0 | AR22: 6.8 | AS22: =IF(AR22<=Sheet2!$D$2,Sheet2!$C$2,IF(AR22<=Sheet2!$D$3,Sheet2!$C$3,IF(AR22<=Sheet2!$D$4,Sheet2!$C$4,IF(AR22<=Sheet2!$D$5,Sheet2!$C$5,IF(AR22<=Sheet2!$D$6,Sheet2!$C$6,IF(AR22<=Sheet2!$D$7,Sheet2!$C$7,IF(AR22<=Sheet2!$D$8,Sheet2!$C$8,IF(AR22<=Sheet2!$D$9,Sheet2!$C$9,IF(AR22<=Sheet2!$D$10,Sheet2!$C$10,IF(AR22<=Sheet2!$D$11,Sheet2!$C$11,0)))))))))) -> 533 | AT22: =AS22-V22 -> 428 | AY22: =AS22/H22 -> 5.381664 | AZ22: =(AR22/H22*1000)*3.4 -> 233.44103 | BA22: VRV-GF-Common Areas | BB22: =IF(AR22<=Sheet2!$D$2,Sheet2!$B$2,IF(AR22<=Sheet2!$D$3,Sheet2!$B$3,IF(AR22<=Sheet2!$D$4,Sheet2!$B$4,IF(AR22<=Sheet2!$D$5,Sheet2!$B$5,IF(AR22<=Sheet2!$D$6,Sheet2!$B$6,IF(AR22<=Sheet2!$D$7,Sheet2!$B$7,IF(AR22<=Sheet2!$D$8,Sheet2!$B$8,IF(AR22<=Sheet2!$D$9,Sheet2!$B$9,IF(AR22<=Sheet2!$D$10,Sheet2!$B$10,IF(AR22<=Sheet2!$D$11,Sheet2!$B$11,0)))))))))) -> FXSQ100A
A23: Waiting Area | B23: 19 | C23: Group 10 | D23: GF-018-A | E23: Family Waiting Room | F23: صالة انتظار عائلية | G23: =4*7.9 -> 31.6 | H23: =G23 -> 31.6 | I23: 10 | K23: =I23 -> 10 | L23: 0 | M23: 0 | N23: =VLOOKUP(A23,Data!A:B,2,FALSE) -> 50 | O23: =L23 -> 0 | P23: 22 | Q23: <60 | R23: =VLOOKUP(A23,Data!A:D,4,FALSE) -> 3.8 | S23: =VLOOKUP(A23,Data!A:C,3,FALSE) -> 0.3 | U23: =R23*I23+S23*G23 -> 47.48 | V23: =CEILING(U23,5) -> 50 | Z23: =0.85*V23 -> 42.5 | AA23: =CEILING(Z23,1) -> 43 | AC23: -40 | AD23: =IF(V23+W23+AB23 > 0, "Positive", IF(V23-+W23+AB23 < 0, "Negative", "Neutral")) -> Positive | AE23: =ROUND(ABS((V23+AB23+W23+AC23)*3.6)/(G23*3),2) -> 0.38 | AF23: =AND(AE23>=0.3,AE23<=0.8) -> TRUE | AK23: =VLOOKUP(A23,Data!A:F,6,FALSE) -> 10 | AL23: =AK23*G23/1000 -> 0.316 | AM23: =AL23 -> 0.316 | AP23: 1 | AQ23: =AO23/AP23 -> 0 | AR23: 4.1 | AS23: =IF(AR23<=Sheet2!$D$2,Sheet2!$C$2,IF(AR23<=Sheet2!$D$3,Sheet2!$C$3,IF(AR23<=Sheet2!$D$4,Sheet2!$C$4,IF(AR23<=Sheet2!$D$5,Sheet2!$C$5,IF(AR23<=Sheet2!$D$6,Sheet2!$C$6,IF(AR23<=Sheet2!$D$7,Sheet2!$C$7,IF(AR23<=Sheet2!$D$8,Sheet2!$C$8,IF(AR23<=Sheet2!$D$9,Sheet2!$C$9,IF(AR23<=Sheet2!$D$10,Sheet2!$C$10,IF(AR23<=Sheet2!$D$11,Sheet2!$C$11,0)))))))))) -> 350 | AT23: =AS23-V23 -> 300 | AY23: =AS23/H23 -> 11.075949 | AZ23: =(AR23/H23*1000)*3.4 -> 441.13924 | BA23: VRV-GF-Common Areas | BB23: =IF(AR23<=Sheet2!$D$2,Sheet2!$B$2,IF(AR23<=Sheet2!$D$3,Sheet2!$B$3,IF(AR23<=Sheet2!$D$4,Sheet2!$B$4,IF(AR23<=Sheet2!$D$5,Sheet2!$B$5,IF(AR23<=Sheet2!$D$6,Sheet2!$B$6,IF(AR23<=Sheet2!$D$7,Sheet2!$B$7,IF(AR23<=Sheet2!$D$8,Sheet2!$B$8,IF(AR23<=Sheet2!$D$9,Sheet2!$B$9,IF(AR23<=Sheet2!$D$10,Sheet2!$B$10,IF(AR23<=Sheet2!$D$11,Sheet2!$B$11,0)))))))))) -> FXSQ63A
A24: Waiting Area | B24: 20 | C24: Group 10 | D24: GF-018-B | E24: Family Waiting Room | F24: صالة انتظار عائلية | G24: =4*7.9 -> 31.6 | H24: =G24 -> 31.6 | I24: 17 | K24: =I24 -> 17 | L24: 0 | M24: 0 | N24: =VLOOKUP(A24,Data!A:B,2,FALSE) -> 50 | O24: =L24 -> 0 | P24: 22 | Q24: <60 | R24: =VLOOKUP(A24,Data!A:D,4,FALSE) -> 3.8 | S24: =VLOOKUP(A24,Data!A:C,3,FALSE) -> 0.3 | U24: =R24*I24+S24*G24 -> 74.08 | V24: =CEILING(U24,5) -> 75 | Z24: =0.85*V24 -> 63.75 | AA24: 75 | AC24: -65 | AD24: =IF(V24+W24+AB24 > 0, "Positive", IF(V24-+W24+AB24 < 0, "Negative", "Neutral")) -> Positive | AE24: =ROUND(ABS((V24+AB24+W24+AC24)*3.6)/(G24*3),2) -> 0.38 | AF24: =AND(AE24>=0.3,AE24<=0.8) -> TRUE | AK24: =VLOOKUP(A24,Data!A:F,6,FALSE) -> 10 | AL24: =AK24*G24/1000 -> 0.316 | AM24: =AL24 -> 0.316 | AP24: 1 | AQ24: =AO24/AP24 -> 0 | AR24: 3.8 | AS24: =IF(AR24<=Sheet2!$D$2,Sheet2!$C$2,IF(AR24<=Sheet2!$D$3,Sheet2!$C$3,IF(AR24<=Sheet2!$D$4,Sheet2!$C$4,IF(AR24<=Sheet2!$D$5,Sheet2!$C$5,IF(AR24<=Sheet2!$D$6,Sheet2!$C$6,IF(AR24<=Sheet2!$D$7,Sheet2!$C$7,IF(AR24<=Sheet2!$D$8,Sheet2!$C$8,IF(AR24<=Sheet2!$D$9,Sheet2!$C$9,IF(AR24<=Sheet2!$D$10,Sheet2!$C$10,IF(AR24<=Sheet2!$D$11,Sheet2!$C$11,0)))))))))) -> 350 | AT24: =AS24-V24 -> 275 | AY24: =AS24/H24 -> 11.075949 | AZ24: =(AR24/H24*1000)*3.4 -> 408.86076 | BA24: VRV-GF-Common Areas | BB24: =IF(AR24<=Sheet2!$D$2,Sheet2!$B$2,IF(AR24<=Sheet2!$D$3,Sheet2!$B$3,IF(AR24<=Sheet2!$D$4,Sheet2!$B$4,IF(AR24<=Sheet2!$D$5,Sheet2!$B$5,IF(AR24<=Sheet2!$D$6,Sheet2!$B$6,IF(AR24<=Sheet2!$D$7,Sheet2!$B$7,IF(AR24<=Sheet2!$D$8,Sheet2!$B$8,IF(AR24<=Sheet2!$D$9,Sheet2!$B$9,IF(AR24<=Sheet2!$D$10,Sheet2!$B$10,IF(AR24<=Sheet2!$D$11,Sheet2!$B$11,0)))))))))) -> FXSQ63A
A25: Office | B25: 21 | C25: Group 10 | D25: GF-018-C | E25: Security Office | F25: مكتب امن | G25: =3.4*2.8 -> 9.52 | H25: =G25 -> 9.52 | I25: 1 | K25: =I25 -> 1 | L25: 0 | M25: 0 | N25: =VLOOKUP(A25,Data!A:B,2,FALSE) -> 5 | O25: =L25 -> 0 | P25: 22 | Q25: <60 | R25: =VLOOKUP(A25,Data!A:D,4,FALSE) -> 2.5 | S25: =VLOOKUP(A25,Data!A:C,3,FALSE) -> 0.3 | U25: =R25*I25+S25*G25 -> 5.356 | V25: =CEILING(U25,5) -> 10 | Z25: =0.85*V25 -> 8.5 | AA25: =CEILING(Z25,1) -> 9 | AC25: -7 | AD25: =IF(V25+W25+AB25 > 0, "Positive", IF(V25-+W25+AB25 < 0, "Negative", "Neutral")) -> Positive | AE25: =ROUND(ABS((V25+AB25+W25+AC25)*3.6)/(G25*3),2) -> 0.38 | AF25: =AND(AE25>=0.3,AE25<=0.8) -> TRUE | AK25: =VLOOKUP(A25,Data!A:F,6,FALSE) -> 10 | AL25: =AK25*G25/1000 -> 0.0952 | AM25: =AL25 -> 0.0952 | AP25: 1 | AQ25: =AO25/AP25 -> 0 | AR25: 5.6 | AS25: =IF(AR25<=Sheet2!$D$2,Sheet2!$C$2,IF(AR25<=Sheet2!$D$3,Sheet2!$C$3,IF(AR25<=Sheet2!$D$4,Sheet2!$C$4,IF(AR25<=Sheet2!$D$5,Sheet2!$C$5,IF(AR25<=Sheet2!$D$6,Sheet2!$C$6,IF(AR25<=Sheet2!$D$7,Sheet2!$C$7,IF(AR25<=Sheet2!$D$8,Sheet2!$C$8,IF(AR25<=Sheet2!$D$9,Sheet2!$C$9,IF(AR25<=Sheet2!$D$10,Sheet2!$C$10,IF(AR25<=Sheet2!$D$11,Sheet2!$C$11,0)))))))))) -> 383 | AT25: =AS25-V25 -> 373 | AY25: =AS25/H25 -> 40.231092 | AZ25: =(AR25/H25*1000)*3.4 -> 2000 | BA25: VRV-GF-Common Areas | BB25: =IF(AR25<=Sheet2!$D$2,Sheet2!$B$2,IF(AR25<=Sheet2!$D$3,Sheet2!$B$3,IF(AR25<=Sheet2!$D$4,Sheet2!$B$4,IF(AR25<=Sheet2!$D$5,Sheet2!$B$5,IF(AR25<=Sheet2!$D$6,Sheet2!$B$6,IF(AR25<=Sheet2!$D$7,Sheet2!$B$7,IF(AR25<=Sheet2!$D$8,Sheet2!$B$8,IF(AR25<=Sheet2!$D$9,Sheet2!$B$9,IF(AR25<=Sheet2!$D$10,Sheet2!$B$10,IF(AR25<=Sheet2!$D$11,Sheet2!$B$11,0)))))))))) -> FXSQ80A
A26: Corridor | B26: 22 | C26: Group 8 | D26: GF-018-D | E26: Corridor | G26: 84 | H26: =G26 -> 84 | I26: 0 | K26: =I26 -> 0 | L26: 0 | M26: 0 | N26: =VLOOKUP(A26,Data!A:B,2,FALSE) -> 0 | O26: =L26 -> 0 | P26: 22 | Q26: <60 | R26: =VLOOKUP(A26,Data!A:D,4,FALSE) -> 0 | S26: =VLOOKUP(A26,Data!A:C,3,FALSE) -> 0.3 | U26: =R26*I26+S26*G26 -> 25.2 | V26: 50 | Z26: =0.85*V26 -> 42.5 | AB26: 0 | AD26: =IF(V26+W26+AB26 > 0, "Positive", IF(V26-+W26+AB26 < 0, "Negative", "Neutral")) -> Positive | AE26: =ROUND(ABS((V26+AB26+W26+AC26)*3.6)/(G26*3),2) -> 0.71 | AF26: =AND(AE26>=0.3,AE26<=0.8) -> TRUE | AK26: =VLOOKUP(A26,Data!A:F,6,FALSE) -> 10 | AL26: =AK26*G26/1000 -> 0.84 | AM26: =AL26 -> 0.84 | AP26: 1 | AQ26: =AO26/AP26 -> 0 | AR26: 4.2 | AS26: =IF(AR26<=Sheet2!$D$2,Sheet2!$C$2,IF(AR26<=Sheet2!$D$3,Sheet2!$C$3,IF(AR26<=Sheet2!$D$4,Sheet2!$C$4,IF(AR26<=Sheet2!$D$5,Sheet2!$C$5,IF(AR26<=Sheet2!$D$6,Sheet2!$C$6,IF(AR26<=Sheet2!$D$7,Sheet2!$C$7,IF(AR26<=Sheet2!$D$8,Sheet2!$C$8,IF(AR26<=Sheet2!$D$9,Sheet2!$C$9,IF(AR26<=Sheet2!$D$10,Sheet2!$C$10,IF(AR26<=Sheet2!$D$11,Sheet2!$C$11,0)))))))))) -> 350 | AT26: =AS26-V26 -> 300 | AY26: =AS26/H26 -> 4.1666667 | AZ26: =(AR26/H26*1000)*3.4 -> 170 | BA26: VRV-GF-Common Areas | BB26: =IF(AR26<=Sheet2!$D$2,Sheet2!$B$2,IF(AR26<=Sheet2!$D$3,Sheet2!$B$3,IF(AR26<=Sheet2!$D$4,Sheet2!$B$4,IF(AR26<=Sheet2!$D$5,Sheet2!$B$5,IF(AR26<=Sheet2!$D$6,Sheet2!$B$6,IF(AR26<=Sheet2!$D$7,Sheet2!$B$7,IF(AR26<=Sheet2!$D$8,Sheet2!$B$8,IF(AR26<=Sheet2!$D$9,Sheet2!$B$9,IF(AR26<=Sheet2!$D$10,Sheet2!$B$10,IF(AR26<=Sheet2!$D$11,Sheet2!$B$11,0)))))))))) -> FXSQ63A
A27: Corridor | B27: 23 | C27: Group 9 | D27: GF-018-E | E27: Corridor | G27: =76+4 -> 80 | H27: =G27 -> 80 | I27: 0 | K27: =I27 -> 0 | L27: 0 | M27: 0 | N27: =VLOOKUP(A27,Data!A:B,2,FALSE) -> 0 | O27: =L27 -> 0 | P27: 22 | Q27: <60 | R27: =VLOOKUP(A27,Data!A:D,4,FALSE) -> 0 | S27: =VLOOKUP(A27,Data!A:C,3,FALSE) -> 0.3 | U27: =R27*I27+S27*G27 -> 24 | V27: 310 | W27: -260 | AA27: =CEILING(Z27,1) -> 0 | AB27: =(CEILING(AA27,1))*-1 -> 0 | AD27: =IF(V27+W27+AB27 > 0, "Positive", IF(V27-+W27+AB27 < 0, "Negative", "Neutral")) -> Positive | AE27: =ROUND(ABS((V27+AB27+W27+AC27)*3.6)/(G27*3),2) -> 0.75 | AF27: =AND(AE27>=0.3,AE27<=0.8) -> TRUE | AK27: =VLOOKUP(A27,Data!A:F,6,FALSE) -> 10 | AL27: =AK27*G27/1000 -> 0.8 | AM27: =AL27 -> 0.8 | AP27: 1 | AQ27: =AO27/AP27 -> 0 | AR27: 2.3 | AS27: =IF(AR27<=Sheet2!$D$2,Sheet2!$C$2,IF(AR27<=Sheet2!$D$3,Sheet2!$C$3,IF(AR27<=Sheet2!$D$4,Sheet2!$C$4,IF(AR27<=Sheet2!$D$5,Sheet2!$C$5,IF(AR27<=Sheet2!$D$6,Sheet2!$C$6,IF(AR27<=Sheet2!$D$7,Sheet2!$C$7,IF(AR27<=Sheet2!$D$8,Sheet2!$C$8,IF(AR27<=Sheet2!$D$9,Sheet2!$C$9,IF(AR27<=Sheet2!$D$10,Sheet2!$C$10,IF(AR27<=Sheet2!$D$11,Sheet2!$C$11,0)))))))))) -> 158 | AT27: =AS27-V27 -> -152 | AY27: =AS27/H27 -> 1.975 | AZ27: =(AR27/H27*1000)*3.4 -> 97.75 | BA27: VRV-GF-Common Areas | BB27: =IF(AR27<=Sheet2!$D$2,Sheet2!$B$2,IF(AR27<=Sheet2!$D$3,Sheet2!$B$3,IF(AR27<=Sheet2!$D$4,Sheet2!$B$4,IF(AR27<=Sheet2!$D$5,Sheet2!$B$5,IF(AR27<=Sheet2!$D$6,Sheet2!$B$6,IF(AR27<=Sheet2!$D$7,Sheet2!$B$7,IF(AR27<=Sheet2!$D$8,Sheet2!$B$8,IF(AR27<=Sheet2!$D$9,Sheet2!$B$9,IF(AR27<=Sheet2!$D$10,Sheet2!$B$10,IF(AR27<=Sheet2!$D$11,Sheet2!$B$11,0)))))))))) -> FXSQ32A
A28: Office | B28: 24 | C28: Group 8 | D28: GF-019 | E28: Corporate Social Responsibility Office | F28: مكتب مسؤولية مجتمعية | G28: =4*4.8 -> 19.2 | H28: =G28 -> 19.2 | I28: 3 | K28: =I28 -> 3 | L28: 0 | M28: 0 | N28: =VLOOKUP(A28,Data!A:B,2,FALSE) -> 5 | O28: =L28 -> 0 | P28: 22 | Q28: <60 | R28: =VLOOKUP(A28,Data!A:D,4,FALSE) -> 2.5 | S28: =VLOOKUP(A28,Data!A:C,3,FALSE) -> 0.3 | U28: =R28*I28+S28*G28 -> 13.26 | V28: =CEILING(U28,5) -> 15 | W28: -10 | Z28: =0.85*V28 -> 12.75 | AB28: 0 | AD28: =IF(V28+W28+AB28 > 0, "Positive", IF(V28-+W28+AB28 < 0, "Negative", "Neutral")) -> Positive | AE28: =ROUND(ABS((V28+AB28+W28+AC28)*3.6)/(G28*3),2) -> 0.31 | AF28: =AND(AE28>=0.3,AE28<=0.8) -> TRUE | AK28: =VLOOKUP(A28,Data!A:F,6,FALSE) -> 10 | AL28: =AK28*G28/1000 -> 0.192 | AM28: =AL28 -> 0.192 | AP28: 1 | AQ28: =AO28/AP28 -> 0 | AR28: 2.6 | AS28: =IF(AR28<=Sheet2!$D$2,Sheet2!$C$2,IF(AR28<=Sheet2!$D$3,Sheet2!$C$3,IF(AR28<=Sheet2!$D$4,Sheet2!$C$4,IF(AR28<=Sheet2!$D$5,Sheet2!$C$5,IF(AR28<=Sheet2!$D$6,Sheet2!$C$6,IF(AR28<=Sheet2!$D$7,Sheet2!$C$7,IF(AR28<=Sheet2!$D$8,Sheet2!$C$8,IF(AR28<=Sheet2!$D$9,Sheet2!$C$9,IF(AR28<=Sheet2!$D$10,Sheet2!$C$10,IF(AR28<=Sheet2!$D$11,Sheet2!$C$11,0)))))))))) -> 250 | AT28: =AS28-V28 -> 235 | AY28: =AS28/H28 -> 13.020833 | AZ28: =(AR28/H28*1000)*3.4 -> 460.41667 | BA28: VRV-GF-01 | BB28: =IF(AR28<=Sheet2!$D$2,Sheet2!$B$2,IF(AR28<=Sheet2!$D$3,Sheet2!$B$3,IF(AR28<=Sheet2!$D$4,Sheet2!$B$4,IF(AR28<=Sheet2!$D$5,Sheet2!$B$5,IF(AR28<=Sheet2!$D$6,Sheet2!$B$6,IF(AR28<=Sheet2!$D$7,Sheet2!$B$7,IF(AR28<=Sheet2!$D$8,Sheet2!$B$8,IF(AR28<=Sheet2!$D$9,Sheet2!$B$9,IF(AR28<=Sheet2!$D$10,Sheet2!$B$10,IF(AR28<=Sheet2!$D$11,Sheet2!$B$11,0)))))))))) -> FXSQ40A
A29: mechanical/maintenance room | B29: 25 | C29: Group 8 | D29: GF-020 | E29: Mechanical Room | F29: غرفة خدمات ميكانيكية | G29: =2.8*4.8 -> 13.44 | H29: =G29 -> 13.44 | I29: 1 | K29: =I29 -> 1 | L29: 0 | M29: 0 | N29: =VLOOKUP(A29,Data!A:B,2,FALSE) -> 0 | O29: =L29 -> 0 | P29: 22 | Q29: <60 | R29: =VLOOKUP(A29,Data!A:D,4,FALSE) -> 0 | S29: =VLOOKUP(A29,Data!A:C,3,FALSE) -> 0.3 | U29: =R29*I29+S29*G29 -> 4.032 | W29: 20 | Z29: =0.85*V29 -> 0 | AA29: 25 | AB29: -25 | AD29: =IF(V29+W29+AB29 > 0, "Positive", IF(V29-+W29+AB29 < 0, "Negative", "Neutral")) -> Negative | AE29: =ROUND(ABS((V29+AB29+W29+AC29)*3.6)/(G29*3),2) -> 0.45 | AF29: =AND(AE29>=0.3,AE29<=0.8) -> TRUE | AK29: =VLOOKUP(A29,Data!A:F,6,FALSE) -> 10 | AL29: =AK29*G29/1000 -> 0.1344 | AM29: =AL29 -> 0.1344 | AP29: 1 | AQ29: =AO29/AP29 -> 0 | AR29: 1.5 | AS29: =IF(AR29<=Sheet2!$D$2,Sheet2!$C$2,IF(AR29<=Sheet2!$D$3,Sheet2!$C$3,IF(AR29<=Sheet2!$D$4,Sheet2!$C$4,IF(AR29<=Sheet2!$D$5,Sheet2!$C$5,IF(AR29<=Sheet2!$D$6,Sheet2!$C$6,IF(AR29<=Sheet2!$D$7,Sheet2!$C$7,IF(AR29<=Sheet2!$D$8,Sheet2!$C$8,IF(AR29<=Sheet2!$D$9,Sheet2!$C$9,IF(AR29<=Sheet2!$D$10,Sheet2!$C$10,IF(AR29<=Sheet2!$D$11,Sheet2!$C$11,0)))))))))) -> 150 | AT29: =AS29-V29 -> 150 | AY29: =AS29/H29 -> 11.160714 | AZ29: =(AR29/H29*1000)*3.4 -> 379.46429 | BA29: VRV-GF-01 | BB29: =IF(AR29<=Sheet2!$D$2,Sheet2!$B$2,IF(AR29<=Sheet2!$D$3,Sheet2!$B$3,IF(AR29<=Sheet2!$D$4,Sheet2!$B$4,IF(AR29<=Sheet2!$D$5,Sheet2!$B$5,IF(AR29<=Sheet2!$D$6,Sheet2!$B$6,IF(AR29<=Sheet2!$D$7,Sheet2!$B$7,IF(AR29<=Sheet2!$D$8,Sheet2!$B$8,IF(AR29<=Sheet2!$D$9,Sheet2!$B$9,IF(AR29<=Sheet2!$D$10,Sheet2!$B$10,IF(AR29<=Sheet2!$D$11,Sheet2!$B$11,0)))))))))) -> FXSQ20A
A30: Office | B30: 26 | C30: Group 8 | D30: GF-021 | E30: Operational Services Room | F30: غرفة خدمات تشغيلية | G30: =2.9*4.8 -> 13.92 | H30: =G30 -> 13.92 | I30: 1 | K30: =I30 -> 1 | L30: 0 | M30: 0 | N30: =VLOOKUP(A30,Data!A:B,2,FALSE) -> 5 | O30: =L30 -> 0 | P30: 22 | Q30: <60 | R30: =VLOOKUP(A30,Data!A:D,4,FALSE) -> 2.5 | S30: =VLOOKUP(A30,Data!A:C,3,FALSE) -> 0.3 | U30: =R30*I30+S30*G30 -> 6.676 | V30: =CEILING(U30,5) -> 10 | W30: -5 | Z30: =0.85*V30 -> 8.5 | AB30: 0 | AD30: =IF(V30+W30+AB30 > 0, "Positive", IF(V30-+W30+AB30 < 0, "Negative", "Neutral")) -> Positive | AE30: =ROUND(ABS((V30+AB30+W30+AC30)*3.6)/(G30*3),2) -> 0.43 | AF30: =AND(AE30>=0.3,AE30<=0.8) -> TRUE | AK30: =VLOOKUP(A30,Data!A:F,6,FALSE) -> 10 | AL30: =AK30*G30/1000 -> 0.1392 | AM30: =AL30 -> 0.1392 | AP30: 1 | AQ30: =AO30/AP30 -> 0 | AR30: 1.6 | AS30: =IF(AR30<=Sheet2!$D$2,Sheet2!$C$2,IF(AR30<=Sheet2!$D$3,Sheet2!$C$3,IF(AR30<=Sheet2!$D$4,Sheet2!$C$4,IF(AR30<=Sheet2!$D$5,Sheet2!$C$5,IF(AR30<=Sheet2!$D$6,Sheet2!$C$6,IF(AR30<=Sheet2!$D$7,Sheet2!$C$7,IF(AR30<=Sheet2!$D$8,Sheet2!$C$8,IF(AR30<=Sheet2!$D$9,Sheet2!$C$9,IF(AR30<=Sheet2!$D$10,Sheet2!$C$10,IF(AR30<=Sheet2!$D$11,Sheet2!$C$11,0)))))))))) -> 150 | AT30: =AS30-V30 -> 140 | AY30: =AS30/H30 -> 10.775862 | AZ30: =(AR30/H30*1000)*3.4 -> 390.8046 | BA30: VRV-GF-01 | BB30: =IF(AR30<=Sheet2!$D$2,Sheet2!$B$2,IF(AR30<=Sheet2!$D$3,Sheet2!$B$3,IF(AR30<=Sheet2!$D$4,Sheet2!$B$4,IF(AR30<=Sheet2!$D$5,Sheet2!$B$5,IF(AR30<=Sheet2!$D$6,Sheet2!$B$6,IF(AR30<=Sheet2!$D$7,Sheet2!$B$7,IF(AR30<=Sheet2!$D$8,Sheet2!$B$8,IF(AR30<=Sheet2!$D$9,Sheet2!$B$9,IF(AR30<=Sheet2!$D$10,Sheet2!$B$10,IF(AR30<=Sheet2!$D$11,Sheet2!$B$11,0)))))))))) -> FXSQ25A
A31: Storage | B31: 27 | C31: Group 8 | D31: GF-022 | E31: Water Bottle Storage Room | F31: غرفة تخزين عبوات مياه الشرب | G31: =3.8*4.8 -> 18.24 | H31: =G31 -> 18.24 | I31: 1 | K31: =I31 -> 1 | L31: 0 | M31: 0 | N31: =VLOOKUP(A31,Data!A:B,2,FALSE) -> 2 | O31: =L31 -> 0 | P31: 22 | Q31: <60 | R31: =VLOOKUP(A31,Data!A:D,4,FALSE) -> 0 | S31: =VLOOKUP(A31,Data!A:C,3,FALSE) -> 0 | U31: =R31*I31+S31*G31 -> 0 | W31: 20 | Z31: =0.85*V31 -> 0 | AA31: 25 | AB31: -25 | AD31: =IF(V31+W31+AB31 > 0, "Positive", IF(V31-+W31+AB31 < 0, "Negative", "Neutral")) -> Negative | AE31: =ROUND(ABS((V31+AB31+W31+AC31)*3.6)/(G31*3),2) -> 0.33 | AF31: =AND(AE31>=0.3,AE31<=0.8) -> TRUE | AK31: =VLOOKUP(A31,Data!A:F,6,FALSE) -> 10 | AL31: =AK31*G31/1000 -> 0.1824 | AM31: =AL31 -> 0.1824 | AP31: 1 | AQ31: =AO31/AP31 -> 0 | AR31: 1.9 | AS31: =IF(AR31<=Sheet2!$D$2,Sheet2!$C$2,IF(AR31<=Sheet2!$D$3,Sheet2!$C$3,IF(AR31<=Sheet2!$D$4,Sheet2!$C$4,IF(AR31<=Sheet2!$D$5,Sheet2!$C$5,IF(AR31<=Sheet2!$D$6,Sheet2!$C$6,IF(AR31<=Sheet2!$D$7,Sheet2!$C$7,IF(AR31<=Sheet2!$D$8,Sheet2!$C$8,IF(AR31<=Sheet2!$D$9,Sheet2!$C$9,IF(AR31<=Sheet2!$D$10,Sheet2!$C$10,IF(AR31<=Sheet2!$D$11,Sheet2!$C$11,0)))))))))) -> 158 | AT31: =AS31-V31 -> 158 | AY31: =AS31/H31 -> 8.6622807 | AZ31: =(AR31/H31*1000)*3.4 -> 354.16667 | BA31: VRV-GF-01 | BB31: =IF(AR31<=Sheet2!$D$2,Sheet2!$B$2,IF(AR31<=Sheet2!$D$3,Sheet2!$B$3,IF(AR31<=Sheet2!$D$4,Sheet2!$B$4,IF(AR31<=Sheet2!$D$5,Sheet2!$B$5,IF(AR31<=Sheet2!$D$6,Sheet2!$B$6,IF(AR31<=Sheet2!$D$7,Sheet2!$B$7,IF(AR31<=Sheet2!$D$8,Sheet2!$B$8,IF(AR31<=Sheet2!$D$9,Sheet2!$B$9,IF(AR31<=Sheet2!$D$10,Sheet2!$B$10,IF(AR31<=Sheet2!$D$11,Sheet2!$B$11,0)))))))))) -> FXSQ32A
A32: Office | B32: 28 | C32: Group 8 | D32: GF-023 | E32: Customer Service Lounge | F32: استراحة خدمة العملاء | G32: 44.4 | H32: =G32 -> 44.4 | I32: 17 | K32: =I32 -> 17 | L32: 0 | M32: 1 | N32: =VLOOKUP(A32,Data!A:B,2,FALSE) -> 5 | O32: =L32 -> 0 | P32: 22 | Q32: <60 | R32: =VLOOKUP(A32,Data!A:D,4,FALSE) -> 2.5 | S32: =VLOOKUP(A32,Data!A:C,3,FALSE) -> 0.3 | U32: =R32*I32+S32*G32 -> 55.82 | V32: =CEILING(U32,5) -> 60 | W32: -20 | Z32: =0.85*V32 -> 51 | AB32: -25 | AD32: =IF(V32+W32+AB32 > 0, "Positive", IF(V32-+W32+AB32 < 0, "Negative", "Neutral")) -> Positive | AE32: =ROUND(ABS((V32+AB32+W32+AC32)*3.6)/(G32*3),2) -> 0.41 | AF32: =AND(AE32>=0.3,AE32<=0.8) -> TRUE | AK32: =VLOOKUP(A32,Data!A:F,6,FALSE) -> 10 | AL32: =AK32*G32/1000 -> 0.444 | AM32: =AL32 -> 0.444 | AP32: 1 | AQ32: =AO32/AP32 -> 0 | AR32: 5.8 | AS32: =IF(AR32<=Sheet2!$D$2,Sheet2!$C$2,IF(AR32<=Sheet2!$D$3,Sheet2!$C$3,IF(AR32<=Sheet2!$D$4,Sheet2!$C$4,IF(AR32<=Sheet2!$D$5,Sheet2!$C$5,IF(AR32<=Sheet2!$D$6,Sheet2!$C$6,IF(AR32<=Sheet2!$D$7,Sheet2!$C$7,IF(AR32<=Sheet2!$D$8,Sheet2!$C$8,IF(AR32<=Sheet2!$D$9,Sheet2!$C$9,IF(AR32<=Sheet2!$D$10,Sheet2!$C$10,IF(AR32<=Sheet2!$D$11,Sheet2!$C$11,0)))))))))) -> 383 | AT32: =AS32-V32 -> 323 | AY32: =AS32/H32 -> 8.6261261 | AZ32: =(AR32/H32*1000)*3.4 -> 444.14414 | BA32: VRV-GF-01 | BB32: =IF(AR32<=Sheet2!$D$2,Sheet2!$B$2,IF(AR32<=Sheet2!$D$3,Sheet2!$B$3,IF(AR32<=Sheet2!$D$4,Sheet2!$B$4,IF(AR32<=Sheet2!$D$5,Sheet2!$B$5,IF(AR32<=Sheet2!$D$6,Sheet2!$B$6,IF(AR32<=Sheet2!$D$7,Sheet2!$B$7,IF(AR32<=Sheet2!$D$8,Sheet2!$B$8,IF(AR32<=Sheet2!$D$9,Sheet2!$B$9,IF(AR32<=Sheet2!$D$10,Sheet2!$B$10,IF(AR32<=Sheet2!$D$11,Sheet2!$B$11,0)))))))))) -> FXSQ80A
A33: mechanical/maintenance room | B33: 29 | C33: Group 8 | D33: GF-024 | E33: Maintenance Room | F33: غرفة صيانة | G33: =3.3*6.6 -> 21.78 | H33: =G33 -> 21.78 | I33: 0 | K33: =I33 -> 0 | L33: 0 | M33: 1 | N33: =VLOOKUP(A33,Data!A:B,2,FALSE) -> 0 | O33: =L33 -> 0 | P33: 22 | Q33: <60 | R33: =VLOOKUP(A33,Data!A:D,4,FALSE) -> 0 | S33: =VLOOKUP(A33,Data!A:C,3,FALSE) -> 0.3 | U33: =R33*I33+S33*G33 -> 6.534 | W33: 15 | Z33: =0.85*V33 -> 0 | AA33: 25 | AB33: -25 | AD33: =IF(V33+W33+AB33 > 0, "Positive", IF(V33-+W33+AB33 < 0, "Negative", "Neutral")) -> Negative | AE33: =ROUND(ABS((V33+AB33+W33+AC33)*3.6)/(G33*3),2) -> 0.55 | AF33: =AND(AE33>=0.3,AE33<=0.8) -> TRUE | AK33: =VLOOKUP(A33,Data!A:F,6,FALSE) -> 10 | AL33: =AK33*G33/1000 -> 0.2178 | AM33: =AL33 -> 0.2178 | AP33: 1 | AQ33: =AO33/AP33 -> 0 | AR33: 2.8 | AS33: =IF(AR33<=Sheet2!$D$2,Sheet2!$C$2,IF(AR33<=Sheet2!$D$3,Sheet2!$C$3,IF(AR33<=Sheet2!$D$4,Sheet2!$C$4,IF(AR33<=Sheet2!$D$5,Sheet2!$C$5,IF(AR33<=Sheet2!$D$6,Sheet2!$C$6,IF(AR33<=Sheet2!$D$7,Sheet2!$C$7,IF(AR33<=Sheet2!$D$8,Sheet2!$C$8,IF(AR33<=Sheet2!$D$9,Sheet2!$C$9,IF(AR33<=Sheet2!$D$10,Sheet2!$C$10,IF(AR33<=Sheet2!$D$11,Sheet2!$C$11,0)))))))))) -> 250 | AT33: =AS33-V33 -> 250 | AY33: =AS33/H33 -> 11.478421 | AZ33: =(AR33/H33*1000)*3.4 -> 437.09826 | BA33: VRV-GF-01 | BB33: =IF(AR33<=Sheet2!$D$2,Sheet2!$B$2,IF(AR33<=Sheet2!$D$3,Sheet2!$B$3,IF(AR33<=Sheet2!$D$4,Sheet2!$B$4,IF(AR33<=Sheet2!$D$5,Sheet2!$B$5,IF(AR33<=Sheet2!$D$6,Sheet2!$B$6,IF(AR33<=Sheet2!$D$7,Sheet2!$B$7,IF(AR33<=Sheet2!$D$8,Sheet2!$B$8,IF(AR33<=Sheet2!$D$9,Sheet2!$B$9,IF(AR33<=Sheet2!$D$10,Sheet2!$B$10,IF(AR33<=Sheet2!$D$11,Sheet2!$B$11,0)))))))))) -> FXSQ40A
A34: bathroom | B34: 30 | D34: GF-025 | E34: Women's Rest Room | F34: دورة مياه نساء | G34: =5.1*5.9 -> 30.09 | H34: =G34 -> 30.09 | I34: 5 | K34: =I34 -> 5 | L34: 0 | M34: 8 | N34: =VLOOKUP(A34,Data!A:B,2,FALSE) -> 0 | O34: =L34 -> 0 | P34: 22 | Q34: <60 | R34: =VLOOKUP(A34,Data!A:D,4,FALSE) -> 0 | S34: =VLOOKUP(A34,Data!A:C,3,FALSE) -> 0 | U34: =R34*I34+S34*G34 -> 0 | V34: =CEILING(U34,5) -> 0 | X34: 25 | Y34: 6 | Z34: =Y34*X34 -> 150 | AA34: =CEILING(Z34,1) -> 150 | AB34: =(CEILING(AA34,1))*-1 -> -150 | AD34: =IF(V34+W34+AB34 > 0, "Positive", IF(V34-+W34+AB34 < 0, "Negative", "Neutral")) -> Negative | AE34: =ROUND(ABS((V34+AB34+W34+AC34)*3.6)/(G34*3),2) -> 5.98 | AF34: =AND(AE34>=0.3,AE34<=0.8) -> FALSE | AK34: =VLOOKUP(A34,Data!A:F,6,FALSE) -> 10 | AL34: =AK34*G34/1000 -> 0.3009 | AM34: =AL34 -> 0.3009 | AP34: 1 | AQ34: =AO34/AP34 -> 0 | AR34: 2.8 | AS34: =IF(AR34<=Sheet2!$D$2,Sheet2!$C$2,IF(AR34<=Sheet2!$D$3,Sheet2!$C$3,IF(AR34<=Sheet2!$D$4,Sheet2!$C$4,IF(AR34<=Sheet2!$D$5,Sheet2!$C$5,IF(AR34<=Sheet2!$D$6,Sheet2!$C$6,IF(AR34<=Sheet2!$D$7,Sheet2!$C$7,IF(AR34<=Sheet2!$D$8,Sheet2!$C$8,IF(AR34<=Sheet2!$D$9,Sheet2!$C$9,IF(AR34<=Sheet2!$D$10,Sheet2!$C$10,IF(AR34<=Sheet2!$D$11,Sheet2!$C$11,0)))))))))) -> 250 | AT34: =AS34-V34 -> 250 | AZ34: =(AR34/H34*1000)*3.4 -> 316.38418 | BA34: Served By RTU-01
A35: Ablution | B35: 31 | D35: GF-026 | E35: Ablution | F35: موضى | G35: =4*3.5 -> 14 | H35: =G35 -> 14 | I35: 6 | K35: =I35 -> 6 | L35: 0 | M35: 1 | N35: =VLOOKUP(A35,Data!A:B,2,FALSE) -> 0 | O35: =L35 -> 0 | P35: 22 | Q35: <60 | R35: =VLOOKUP(A35,Data!A:D,4,FALSE) -> 0 | S35: =VLOOKUP(A35,Data!A:C,3,FALSE) -> 0 | U35: =AA35*0.85 -> 15.3 | V35: =CEILING(U35,5) -> 20 | X35: =VLOOKUP(A35,Data!A:E,5,FALSE) -> 1.25 | Z35: =G35*X35 -> 17.5 | AA35: =CEILING(Z35,1) -> 18 | AB35: =(CEILING(AA35,1))*-1 -> -18 | AD35: =IF(V35+W35+AB35 > 0, "Positive", IF(V35-+W35+AB35 < 0, "Negative", "Neutral")) -> Positive | AE35: =ROUND(ABS((V35+AB35+W35+AC35)*3.6)/(G35*3),2) -> 0.17 | AF35: =AND(AE35>=0.3,AE35<=0.8) -> FALSE | AK35: =VLOOKUP(A35,Data!A:F,6,FALSE) -> 10 | AL35: =AK35*G35/1000 -> 0.14 | AM35: =AL35 -> 0.14 | AP35: 1 | AQ35: =AO35/AP35 -> 0 | AR35: 5.6 | AS35: =IF(AR35<=Sheet2!$D$2,Sheet2!$C$2,IF(AR35<=Sheet2!$D$3,Sheet2!$C$3,IF(AR35<=Sheet2!$D$4,Sheet2!$C$4,IF(AR35<=Sheet2!$D$5,Sheet2!$C$5,IF(AR35<=Sheet2!$D$6,Sheet2!$C$6,IF(AR35<=Sheet2!$D$7,Sheet2!$C$7,IF(AR35<=Sheet2!$D$8,Sheet2!$C$8,IF(AR35<=Sheet2!$D$9,Sheet2!$C$9,IF(AR35<=Sheet2!$D$10,Sheet2!$C$10,IF(AR35<=Sheet2!$D$11,Sheet2!$C$11,0)))))))))) -> 383 | AT35: =AS35-V35 -> 363 | AZ35: =(AR35/H35*1000)*3.4 -> 1360 | BA35: Served By RTU-01
A36: Prayer Room | B36: 32 | D36: GF-027 | E36: Prayer Room | F36: مصلى | G36: =6*5.9 -> 35.4 | H36: =G36 -> 35.4 | I36: 25 | K36: =I36 -> 25 | L36: 0 | M36: 3 | N36: =VLOOKUP(A36,Data!A:B,2,FALSE) -> 120 | O36: =L36 -> 0 | P36: 22 | Q36: <60 | R36: =VLOOKUP(A36,Data!A:D,4,FALSE) -> 2.5 | S36: =VLOOKUP(A36,Data!A:C,3,FALSE) -> 0.3 | U36: =R36*I36+S36*G36 -> 73.12 | V36: =CEILING(U36,5) -> 75 | Z36: =0.85*V36 -> 63.75 | AA36: =CEILING(Z36,1) -> 64 | AB36: =(CEILING(AA36,1))*-1 -> -64 | AD36: =IF(V36+W36+AB36 > 0, "Positive", IF(V36-+W36+AB36 < 0, "Negative", "Neutral")) -> Positive | AE36: =ROUND(ABS((V36+AB36+W36+AC36)*3.6)/(G36*3),2) -> 0.37 | AF36: =AND(AE36>=0.3,AE36<=0.8) -> TRUE | AK36: =VLOOKUP(A36,Data!A:F,6,FALSE) -> 10 | AL36: =AK36*G36/1000 -> 0.354 | AM36: =AL36 -> 0.354 | AP36: 1 | AQ36: =AO36/AP36 -> 0 | AR36: 11.9 | AS36: =IF(AR36<=Sheet2!$D$2,Sheet2!$C$2,IF(AR36<=Sheet2!$D$3,Sheet2!$C$3,IF(AR36<=Sheet2!$D$4,Sheet2!$C$4,IF(AR36<=Sheet2!$D$5,Sheet2!$C$5,IF(AR36<=Sheet2!$D$6,Sheet2!$C$6,IF(AR36<=Sheet2!$D$7,Sheet2!$C$7,IF(AR36<=Sheet2!$D$8,Sheet2!$C$8,IF(AR36<=Sheet2!$D$9,Sheet2!$C$9,IF(AR36<=Sheet2!$D$10,Sheet2!$C$10,IF(AR36<=Sheet2!$D$11,Sheet2!$C$11,0)))))))))) -> 0 | AT36: =AS36-V36 -> -75 | AZ36: =(AR36/H36*1000)*3.4 -> 1142.9379 | BA36: Served By RTU-01
